Workbook
Name activity: Ref!$N$3:$N$16
Name activity: Ref!$N$3:$N$16
Name activity: Ref!$N$3:$N$16
Name activity: Ref!$N$3:$N$16
Name budget: Ref!$P$3:$P$6
Name costCtr: Ref!$O$3:$O$35
Name costCtr: Ref!$O$3:$O$35
Name costCtr: Ref!$O$3:$O$35
Name costCtr: Ref!$O$3:$O$44
Name list1: '[1]Daily Accomplishment Report'!$F$12:$F$133
Name list1: '[2]DTR-Detailed'!$F$12:$F$133
Name list1: '[2]DTR-Detailed'!$F$12:$F$133
Name list1: DailyAccomplishmentReport!$S$12:$S$75
Name provider: Ref!$K$3:$K$6
Name provider: Ref!$K$3:$K$6
Name provider: Ref!$K$3:$K$6
Name provider: Ref!$K$3:$K$6
Name s: Ref!$O$3:$O$35
Name section: Ref!$M$3:$M$7
Name section: Ref!$M$3:$M$7
Name section: Ref!$M$3:$M$7
Name section: Ref!$M$3:$M$7
Name teamLead: Ref!$L$3:$L$7
Name teamLead: Ref!$L$3:$L$7
Name teamLead: Ref!$L$3:$L$7
Name teamLead: Ref!$L$3:$L$8

Sheet Instruction
B2: Instructions:
B3: In Daily Accomplishment Report worksheet, provide the following data:
B4: Name
B5: Provider (ex.: SLI, Radix)
B6: Team Lead
B7: Section/Unit
B8: Payroll Perion (To/From)
B9: Date(MM/DD/YY)
B10: Number of Hrs (Regular / OT)
C11: -Saturday, Sunday, Night Differential, Special Holiday(weekdays/Saturday/Sunday), Legal Holiday(weekedays/Saturday/Sunday)
B12: Cost Center
B13: Activity Type
B14: SIR
B15: Description
B16: In Attendance Report* worksheet, provide the following data:
B17: Position
B18: Time-In/Time-Out in Regulars (HH:MM) - required format is Military Time
B19: Time-In/Time-Out in Overtime (HH:MM) - required format is Military Time
B20: Other data are automatically populated or updated based on the value in Daily Accomplishment Report worksheet
B24: Legend:
C26: Weekdays
C27: Sunday
C28: Saturday
C29: Special Holidays (Mon-Sat)
C30: Beyond SH (Mon-Sat)
C31: Special Holidays(Sun)
C32: Beyond SH (Sun)
C33: Legal Holidays (Mon-Sat)
C34: Beyond LH (Mon-Sat)
C35: Legal Holidays(Sun)
C36: Beyond LH (Sun)
C37: Night Shift

Sheet DailyAccomplishmentReport
B1: DAILY TIME RECORD
B3: Name : | D3: MIKAELLA ANDREA DEVELOS
B4: Provider : | D4: RADIX
B5: Project Manager : | D5: Jun M. Salvanera
B6: Section/Unit : | D6: BD1
B7: Payroll Period : | D7: From | E7: To
D8: 11/16/25 | E8: 11/30/25 | G8: =DAY(D8) -> #VALUE!
AB9: 1.25 | AC9: 1.25 | AD9: 1.3 | AE9: 1.3 | AF9: 1.69 | AG9: 0.1 | AH9: 1.3 | AI9: 1.69 | AJ9: 1.5 | AK9: 1.95 | AL9: 2 | AM9: 2.6 | AN9: 2.6 | AO9: 3.38
B10: Date | C10: Number of Hours | E10: Saturday (OT) | F10: Saturday (OT>8) | G10: Sunday (OT) | H10: Sunday (OT>8) | I10: Night Diff (10PM - 6 AM) | J10: Special Holiday (<=8) | K10: Special Holiday (>8) | L10: Special Holiday (Sunday <=8) | M10: Special Holiday (Sunday > 8) | N10: Legal Holiday (<=8) | O10: Legal Holiday (>8) | P10: Legal Holiday (Sunday <=8) | Q10: Legal Holiday (Sunday > 8) | R10: SIR | S10: Cost Center | T10: Budget To Be Drawn Form | U10: Activity Type | V10: Description | AB10: Regular (OT > 8) | AC10: Saturday (OT) | AD10: Saturday (OT>8) | AE10: Sunday (OT) | AF10: Sunday (OT>8) | AG10: Night Diff (10PM - 6 AM) | AH10: Special Holiday (<=8) | AI10: Special Holiday (>8) | AJ10: Special Holiday (Sunday <=8) | AK10: Special Holiday (Sunday > 8) | AL10: Legal Holiday (<=8) | AM10: Legal Holiday (>8) | AN10: Legal Holiday (Sunday <=8) | AO10: Legal Holiday (Sunday > 8) | AP10: Total Hours
C11: Regular | D11: OT > 8 | X11: OT(%) | Y11: interest | Z11: day num
B12: 45962 | X12: =ROUND(D12*Y12,2) -> #N/A | Y12: =VLOOKUP(Z12,Ref!$C$3:$D$14,2,FALSE) -> #N/A | Z12: =VLOOKUP(B12,Ref!$F$3:$H$367,3,FALSE) -> #N/A | AB12: =(D12*$AB$9) -> 0 | AC12: =(E12*$AC$9) -> 0 | AD12: =(F12*$AD$9) -> 0 | AE12: =(G12*$AE$9) -> 0 | AF12: =(H12*$AF$9) -> 0 | AG12: =(I12*$AG$9) -> 0 | AH12: =(J12*$AH$9) -> 0 | AI12: =(K12*$AI$9) -> 0 | AJ12: =(L12*$AJ$9) -> 0 | AK12: =(M12*$AK$9) -> 0 | AL12: =(N12*$AL$9) -> 0 | AM12: =(O12*$AM$9) -> 0 | AN12: =(P12*$AN$9) -> 0 | AO12: =(Q12*$AO$9) -> 0 | AP12: =SUM(AB12:AO12) -> 0
B13: 45963 | X13: =ROUND(D13*Y13,2) -> #N/A | Y13: =VLOOKUP(Z13,Ref!$C$3:$D$14,2,FALSE) -> #N/A | Z13: =VLOOKUP(B13,Ref!$F$3:$H$367,3,FALSE) -> #N/A | AB13: =(D13*$AB$9) -> 0 | AC13: =(E13*$AC$9) -> 0 | AD13: =(F13*$AD$9) -> 0 | AE13: =(G13*$AE$9) -> 0 | AF13: =(H13*$AF$9) -> 0 | AG13: =(I13*$AG$9) -> 0 | AH13: =(J13*$AH$9) -> 0 | AI13: =(K13*$AI$9) -> 0 | AJ13: =(L13*$AJ$9) -> 0 | AK13: =(M13*$AK$9) -> 0 | AL13: =(N13*$AL$9) -> 0 | AM13: =(O13*$AM$9) -> 0 | AN13: =(P13*$AN$9) -> 0 | AO13: =(Q13*$AO$9) -> 0 | AP13: =SUM(AB13:AO13) -> 0
B14: 45964 | C14: 8 | S14: OP - IT | V14: Worked on billers module frontend, connecting forms and validation logic. | X14: =ROUND(D14*Y14,2) -> #N/A | Y14: =VLOOKUP(Z14,Ref!$C$3:$D$14,2,FALSE) -> #N/A | Z14: =VLOOKUP(B14,Ref!$F$3:$H$367,3,FALSE) -> #N/A | AB14: =(D14*$AB$9) -> 0 | AC14: =(E14*$AC$9) -> 0 | AD14: =(F14*$AD$9) -> 0 | AE14: =(G14*$AE$9) -> 0 | AF14: =(H14*$AF$9) -> 0 | AG14: =(I14*$AG$9) -> 0 | AH14: =(J14*$AH$9) -> 0 | AI14: =(K14*$AI$9) -> 0 | AJ14: =(L14*$AJ$9) -> 0 | AK14: =(M14*$AK$9) -> 0 | AL14: =(N14*$AL$9) -> 0 | AM14: =(O14*$AM$9) -> 0 | AN14: =(P14*$AN$9) -> 0 | AO14: =(Q14*$AO$9) -> 0 | AP14: =SUM(AB14:AO14) -> 0
B15: 45965 | C15: 8 | S15: OP - IT | V15: Worked on billers module frontend, connecting forms and validation logic. | X15: =ROUND(D15*Y15,2) -> #N/A | Y15: =VLOOKUP(Z15,Ref!$C$3:$D$14,2,FALSE) -> #N/A | Z15: =VLOOKUP(B15,Ref!$F$3:$H$367,3,FALSE) -> #N/A | AB15: =(D15*$AB$9) -> 0 | AC15: =(E15*$AC$9) -> 0 | AD15: =(F15*$AD$9) -> 0 | AE15: =(G15*$AE$9) -> 0 | AF15: =(H15*$AF$9) -> 0 | AG15: =(I15*$AG$9) -> 0 | AH15: =(J15*$AH$9) -> 0 | AI15: =(K15*$AI$9) -> 0 | AJ15: =(L15*$AJ$9) -> 0 | AK15: =(M15*$AK$9) -> 0 | AL15: =(N15*$AL$9) -> 0 | AM15: =(O15*$AM$9) -> 0 | AN15: =(P15*$AN$9) -> 0 | AO15: =(Q15*$AO$9) -> 0 | AP15: =SUM(AB15:AO15) -> 0
B16: 45966 | C16: 8 | S16: OP - IT | V16: Began coding the frontend components for the dashboard, setting up initial UI elements. | X16: =ROUND(D16*Y16,2) -> #N/A | Y16: =VLOOKUP(Z16,Ref!$C$3:$D$14,2,FALSE) -> #N/A | Z16: =VLOOKUP(B16,Ref!$F$3:$H$367,3,FALSE) -> #N/A | AB16: =(D16*$AB$9) -> 0 | AC16: =(E16*$AC$9) -> 0 | AD16: =(F16*$AD$9) -> 0 | AE16: =(G16*$AE$9) -> 0 | AF16: =(H16*$AF$9) -> 0 | AG16: =(I16*$AG$9) -> 0 | AH16: =(J16*$AH$9) -> 0 | AI16: =(K16*$AI$9) -> 0 | AJ16: =(L16*$AJ$9) -> 0 | AK16: =(M16*$AK$9) -> 0 | AL16: =(N16*$AL$9) -> 0 | AM16: =(O16*$AM$9) -> 0 | AN16: =(P16*$AN$9) -> 0 | AO16: =(Q16*$AO$9) -> 0 | AP16: =SUM(AB16:AO16) -> 0
B17: 45967 | C17: 8 | S17: OP - IT | V17: Worked on billers module frontend, connecting forms and validation logic. | X17: =ROUND(D17*Y17,2) -> #N/A | Y17: =VLOOKUP(Z17,Ref!$C$3:$D$14,2,FALSE) -> #N/A | Z17: =VLOOKUP(B17,Ref!$F$3:$H$367,3,FALSE) -> #N/A | AB17: =(D17*$AB$9) -> 0 | AC17: =(E17*$AC$9) -> 0 | AD17: =(F17*$AD$9) -> 0 | AE17: =(G17*$AE$9) -> 0 | AF17: =(H17*$AF$9) -> 0 | AG17: =(I17*$AG$9) -> 0 | AH17: =(J17*$AH$9) -> 0 | AI17: =(K17*$AI$9) -> 0 | AJ17: =(L17*$AJ$9) -> 0 | AK17: =(M17*$AK$9) -> 0 | AL17: =(N17*$AL$9) -> 0 | AM17: =(O17*$AM$9) -> 0 | AN17: =(P17*$AN$9) -> 0 | AO17: =(Q17*$AO$9) -> 0 | AP17: =SUM(AB17:AO17) -> 0
B18: 45968 | C18: 8 | S18: OP - IT | V18: Working on PDF CDeveloped frontend modules for the attendance feature, ensuring usability and accuracy.onverter reseach and implementation how to convert docx to pdf | X18: =ROUND(D18*Y18,2) -> #N/A | Y18: =VLOOKUP(Z18,Ref!$C$3:$D$14,2,FALSE) -> #N/A | Z18: =VLOOKUP(B18,Ref!$F$3:$H$367,3,FALSE) -> #N/A | AB18: =(D18*$AB$9) -> 0 | AC18: =(E18*$AC$9) -> 0 | AD18: =(F18*$AD$9) -> 0 | AE18: =(G18*$AE$9) -> 0 | AF18: =(H18*$AF$9) -> 0 | AG18: =(I18*$AG$9) -> 0 | AH18: =(J18*$AH$9) -> 0 | AI18: =(K18*$AI$9) -> 0 | AJ18: =(L18*$AJ$9) -> 0 | AK18: =(M18*$AK$9) -> 0 | AL18: =(N18*$AL$9) -> 0 | AM18: =(O18*$AM$9) -> 0 | AN18: =(P18*$AN$9) -> 0 | AO18: =(Q18*$AO$9) -> 0 | AP18: =SUM(AB18:AO18) -> 0
B19: 45969 | X19: =ROUND(D19*Y19,2) -> #N/A | Y19: =VLOOKUP(Z19,Ref!$C$3:$D$14,2,FALSE) -> #N/A | Z19: =VLOOKUP(B19,Ref!$F$3:$H$367,3,FALSE) -> #N/A | AB19: =(D19*$AB$9) -> 0 | AC19: =(E19*$AC$9) -> 0 | AD19: =(F19*$AD$9) -> 0 | AE19: =(G19*$AE$9) -> 0 | AF19: =(H19*$AF$9) -> 0 | AG19: =(I19*$AG$9) -> 0 | AH19: =(J19*$AH$9) -> 0 | AI19: =(K19*$AI$9) -> 0 | AJ19: =(L19*$AJ$9) -> 0 | AK19: =(M19*$AK$9) -> 0 | AL19: =(N19*$AL$9) -> 0 | AM19: =(O19*$AM$9) -> 0 | AN19: =(P19*$AN$9) -> 0 | AO19: =(Q19*$AO$9) -> 0 | AP19: =SUM(AB19:AO19) -> 0
B20: 45970 | X20: =ROUND(D20*Y20,2) -> #N/A | Y20: =VLOOKUP(Z20,Ref!$C$3:$D$14,2,FALSE) -> #N/A | Z20: =VLOOKUP(B20,Ref!$F$3:$H$367,3,FALSE) -> #N/A | AB20: =(D20*$AB$9) -> 0 | AC20: =(E20*$AC$9) -> 0 | AD20: =(F20*$AD$9) -> 0 | AE20: =(G20*$AE$9) -> 0 | AF20: =(H20*$AF$9) -> 0 | AG20: =(I20*$AG$9) -> 0 | AH20: =(J20*$AH$9) -> 0 | AI20: =(K20*$AI$9) -> 0 | AJ20: =(L20*$AJ$9) -> 0 | AK20: =(M20*$AK$9) -> 0 | AL20: =(N20*$AL$9) -> 0 | AM20: =(O20*$AM$9) -> 0 | AN20: =(P20*$AN$9) -> 0 | AO20: =(Q20*$AO$9) -> 0 | AP20: =SUM(AB20:AO20) -> 0
B21: 45971 | X21: =ROUND(D21*Y21,2) -> #N/A | Y21: =VLOOKUP(Z21,Ref!$C$3:$D$14,2,FALSE) -> #N/A | Z21: =VLOOKUP(B21,Ref!$F$3:$H$367,3,FALSE) -> #N/A | AB21: =(D21*$AB$9) -> 0 | AC21: =(E21*$AC$9) -> 0 | AD21: =(F21*$AD$9) -> 0 | AE21: =(G21*$AE$9) -> 0 | AF21: =(H21*$AF$9) -> 0 | AG21: =(I21*$AG$9) -> 0 | AH21: =(J21*$AH$9) -> 0 | AI21: =(K21*$AI$9) -> 0 | AJ21: =(L21*$AJ$9) -> 0 | AK21: =(M21*$AK$9) -> 0 | AL21: =(N21*$AL$9) -> 0 | AM21: =(O21*$AM$9) -> 0 | AN21: =(P21*$AN$9) -> 0 | AO21: =(Q21*$AO$9) -> 0 | AP21: =SUM(AB21:AO21) -> 0
B22: 45972 | C22: 8 | S22: OP - IT | V22: Worked on billers module frontend, connecting forms and validation logic. | X22: =ROUND(D22*Y22,2) -> #N/A | Y22: =VLOOKUP(Z22,Ref!$C$3:$D$14,2,FALSE) -> #N/A | Z22: =VLOOKUP(B22,Ref!$F$3:$H$367,3,FALSE) -> #N/A | AB22: =(D22*$AB$9) -> 0 | AC22: =(E22*$AC$9) -> 0 | AD22: =(F22*$AD$9) -> 0 | AE22: =(G22*$AE$9) -> 0 | AF22: =(H22*$AF$9) -> 0 | AG22: =(I22*$AG$9) -> 0 | AH22: =(J22*$AH$9) -> 0 | AI22: =(K22*$AI$9) -> 0 | AJ22: =(L22*$AJ$9) -> 0 | AK22: =(M22*$AK$9) -> 0 | AL22: =(N22*$AL$9) -> 0 | AM22: =(O22*$AM$9) -> 0 | AN22: =(P22*$AN$9) -> 0 | AO22: =(Q22*$AO$9) -> 0 | AP22: =SUM(AB22:AO22) -> 0
B23: 45973 | C23: 5.83 | S23: OP - IT | V23: Adjusted and fixed backend issues | X23: =ROUND(D23*Y23,2) -> #N/A | Y23: =VLOOKUP(Z23,Ref!$C$3:$D$14,2,FALSE) -> #N/A | Z23: =VLOOKUP(B23,Ref!$F$3:$H$367,3,FALSE) -> #N/A | AB23: =(D23*$AB$9) -> 0 | AC23: =(E23*$AC$9) -> 0 | AD23: =(F23*$AD$9) -> 0 | AE23: =(G23*$AE$9) -> 0 | AF23: =(H23*$AF$9) -> 0 | AG23: =(I23*$AG$9) -> 0 | AH23: =(J23*$AH$9) -> 0 | AI23: =(K23*$AI$9) -> 0 | AJ23: =(L23*$AJ$9) -> 0 | AK23: =(M23*$AK$9) -> 0 | AL23: =(N23*$AL$9) -> 0 | AM23: =(O23*$AM$9) -> 0 | AN23: =(P23*$AN$9) -> 0 | AO23: =(Q23*$AO$9) -> 0 | AP23: =SUM(AB23:AO23) -> 0
B24: 45974 | C24: 8 | S24: OP - IT | V24: Finalized backend adjustments | X24: =ROUND(D24*Y24,2) -> #N/A | Y24: =VLOOKUP(Z24,Ref!$C$3:$D$14,2,FALSE) -> #N/A | Z24: =VLOOKUP(B24,Ref!$F$3:$H$367,3,FALSE) -> #N/A | AB24: =(D24*$AB$9) -> 0 | AC24: =(E24*$AC$9) -> 0 | AD24: =(F24*$AD$9) -> 0 | AE24: =(G24*$AE$9) -> 0 | AF24: =(H24*$AF$9) -> 0 | AG24: =(I24*$AG$9) -> 0 | AH24: =(J24*$AH$9) -> 0 | AI24: =(K24*$AI$9) -> 0 | AJ24: =(L24*$AJ$9) -> 0 | AK24: =(M24*$AK$9) -> 0 | AL24: =(N24*$AL$9) -> 0 | AM24: =(O24*$AM$9) -> 0 | AN24: =(P24*$AN$9) -> 0 | AO24: =(Q24*$AO$9) -> 0 | AP24: =SUM(AB24:AO24) -> 0
B25: 45975 | C25: 8 | S25: OP - IT | V25: Conducted thorough debugging across modules | X25: =ROUND(D25*Y25,2) -> #N/A | Y25: =VLOOKUP(Z25,Ref!$C$3:$D$14,2,FALSE) -> #N/A | Z25: =VLOOKUP(B25,Ref!$F$3:$H$367,3,FALSE) -> #N/A | AB25: =(D25*$AB$9) -> 0 | AC25: =(E25*$AC$9) -> 0 | AD25: =(F25*$AD$9) -> 0 | AE25: =(G25*$AE$9) -> 0 | AF25: =(H25*$AF$9) -> 0 | AG25: =(I25*$AG$9) -> 0 | AH25: =(J25*$AH$9) -> 0 | AI25: =(K25*$AI$9) -> 0 | AJ25: =(L25*$AJ$9) -> 0 | AK25: =(M25*$AK$9) -> 0 | AL25: =(N25*$AL$9) -> 0 | AM25: =(O25*$AM$9) -> 0 | AN25: =(P25*$AN$9) -> 0 | AO25: =(Q25*$AO$9) -> 0 | AP25: =SUM(AB25:AO25) -> 0
B26: 45976 | X26: =ROUND(D26*Y26,2) -> #N/A | Y26: =VLOOKUP(Z26,Ref!$C$3:$D$14,2,FALSE) -> #N/A | Z26: =VLOOKUP(B26,Ref!$F$3:$H$367,3,FALSE) -> #N/A | AB26: =(D26*$AB$9) -> 0 | AC26: =(E26*$AC$9) -> 0 | AD26: =(F26*$AD$9) -> 0 | AE26: =(G26*$AE$9) -> 0 | AF26: =(H26*$AF$9) -> 0 | AG26: =(I26*$AG$9) -> 0 | AH26: =(J26*$AH$9) -> 0 | AI26: =(K26*$AI$9) -> 0 | AJ26: =(L26*$AJ$9) -> 0 | AK26: =(M26*$AK$9) -> 0 | AL26: =(N26*$AL$9) -> 0 | AM26: =(O26*$AM$9) -> 0 | AN26: =(P26*$AN$9) -> 0 | AO26: =(Q26*$AO$9) -> 0 | AP26: =SUM(AB26:AO26) -> 0
B27: 45977
B28: 45978 | C28: 8 | S28: OP - IT | V28: Worked on billers module frontend, connecting forms and validation logic.
B29: 45979 | C29: 8 | S29: OP - IT | V29: Worked on billers module frontend, connecting forms and validation logic.
B30: 45980 | C30: 8 | S30: OP - IT | V30: Worked on billers module frontend, connecting forms and validation logic.
B31: 45981 | C31: 8 | S31: OP - IT | V31: Assisted instapay testing
B32: 45982 | C32: 8 | S32: OP - IT | V32: Assisted instapay testing
B33: 45983
B34: 45984
B35: 45985 | C35: 8 | S35: OP - IT | V35: Worked on instapay dashboard
B36: 45986 | C36: 8 | S36: OP - IT | V36: assisted euronet and instapay testing
B37: 45987 | C37: 8 | S37: OP - IT | V37: assisted euronet and instapay testing
B38: 11/27/25 | C38: 8 | S38: OP - IT | V38: assisted euronet and instapay testing
B39: 11/28/25 | C39: 7 | S39: OP - IT | V39: Worked on instapay dashboard's error
B40: 11/29/25
B41: 11/30/25
...

Sheet Attendance Report__First
B1: RADIX
B4: Name | D4: Mikaella Andrea Develos
B5: Shift Schedule | D5: 0.35416667 | E5: 0.72916667 | F5: 0.00069444444 | G5: =E5-F5 -> 0.72847222
B6: Client | D6: Maybank Phil. Inc.
B7: Payroll Period | D7: From | E7: To
D8: 45962 | E8: 45976 | F8: 0.25
E9: 0.91666667 | F9: 1
B10: Date | C10: Regular Hrs | E10: Overtime | G10: Total Hrs | I10: Remarks
C11: In | D11: Out | E11: In | F11: Out | G11: Regular | H11: OT | AB11: Night Diff | AC11: 0.1 | AD11: OTs | AE11: Int(%) | AF11: OT Total
B12: =D8 -> 45962 | G12: =IF(AND(C12="",D12=""),"",IF(AND(C12<=$D$5,D12>=$E$5),8, IF(AND(Q12<4,Q12>0,R12>=0),8-S12,IF(AND(Q12<4,C12>$D$5,U12>5),T12-(S12+1), IF(AND(Q12>3,D12<$E$5),T12-S12,IF(AND(Q12>3,D12>=$E$5),9-S12,IF(AND(C12>$D$5,U12<=4),T12-S12,IF(AND(C12>$D$5,U12>4),U12-(S12+1),IF(AND(C12<=$D$5,U12>=5),T12-1,IF(AND(C12<=$D$5,T12<=4),T12,IF(AND(C12<=$D$5,T12<5),4,IF(U12>5,U12-1,IF(U12<=4,U12,0))))))))))))) | H12: =IF(F12-E12*24=0,"",IF(ROUND((F12-E12)*24,2)>=6,ROUND((F12-E12)*24,2)-1,ROUND((F12-E12)*24,2))) | K12: =Billing!C37 -> 0 | L12: =Billing!D37 -> 0 | M12: ='Attendance Report - Manager'!G27 -> 0 | N12: ='Attendance Report - Manager'!H27 -> 0 | P12: =SUMIF(DailyAccomplishmentReport!$B$12:$B$26,B12,DailyAccomplishmentReport!$AP$12:$AP$26) -> 0 | Q12: =IF(C12<>"", (C12-$D$5)*24,0) -> 0 | R12: =IF(D12<>"", (D12-$E$5)*24,0) -> 0 | S12: =(ROUNDUP(Q12/0.5,0)*0.5 ) -> 0 | T12: =ROUND((D12-$D$5)*24,2) -> -8.5 | U12: =(D12-C12)*24 -> 0 | Z12: =VLOOKUP(B12,Ref!$F$3:$H$367,3,FALSE) -> #N/A | AA12: =SUMIF(DailyAccomplishmentReport!$B$12:$B$43,B12,DailyAccomplishmentReport!$D$12:$D$43) -> 0 | AB12: =IF(F12=$F$9,2,IF(AND(E12>=0,F12<=$F$8),(F12-E12)*24,IF(F12>$E$9,(F12-$E$9)*24,0))) -> 0 | AC12: =ROUND(AB12*$AC$11,2) -> 0 | AD12: =ROUND((F12-E12)*24,2) -> 0 | AE12: =VLOOKUP(Z12,Ref!$C$3:$D$14,2,) -> #N/A | AF12: =AD12*AE12 -> #N/A
B13: =B12+1 -> 45963 | G13: =IF(AND(C13="",D13=""),"",IF(AND(C13<=$D$5,D13>=$E$5),8, IF(AND(Q13<4,Q13>0,R13>=0),8-S13,IF(AND(Q13<4,C13>$D$5,U13>5),T13-(S13+1), IF(AND(Q13>3,D13<$E$5),T13-S13,IF(AND(Q13>3,D13>=$E$5),9-S13,IF(AND(C13>$D$5,U13<=4),T13-S13,IF(AND(C13>$D$5,U13>4),U13-(S13+1),IF(AND(C13<=$D$5,U13>=5),T13-1,IF(AND(C13<=$D$5,T13<=4),T13,IF(AND(C13<=$D$5,T13<5),4,IF(U13>5,U13-1,IF(U13<=4,U13,0))))))))))))) | H13: =IF(F13-E13*24=0,"",IF(ROUND((F13-E13)*24,2)>=6,ROUND((F13-E13)*24,2)-1,ROUND((F13-E13)*24,2))) | K13: =Billing!C38 -> 0 | L13: =Billing!D38 -> 0 | M13: ='Attendance Report - Manager'!G28 -> 0 | N13: ='Attendance Report - Manager'!H28 -> 0 | P13: =SUMIF(DailyAccomplishmentReport!$B$12:$B$26,B13,DailyAccomplishmentReport!$AP$12:$AP$26) -> 0 | Q13: =IF(C13<>"", (C13-$D$5)*24,0) -> 0 | R13: =IF(D13<>"", (D13-$E$5)*24,0) -> 0 | S13: =(ROUNDUP(Q13/0.5,0)*0.5 ) -> 0 | T13: =ROUND((D13-$D$5)*24,2) -> -8.5 | U13: =(D13-C13)*24 -> 0 | Z13: =VLOOKUP(B13,Ref!$F$3:$H$367,3,FALSE) -> #N/A | AA13: =SUMIF(DailyAccomplishmentReport!$B$12:$B$43,B13,DailyAccomplishmentReport!$D$12:$D$43) -> 0 | AB13: =IF(F13=$F$9,2,IF(AND(E13>=0,F13<=$F$8),(F13-E13)*24,IF(F13>$E$9,(F13-$E$9)*24,0))) -> 0 | AC13: =ROUND(AB13*$AC$11,2) -> 0 | AD13: =ROUND((F13-E13)*24,2) -> 0 | AE13: =VLOOKUP(Z13,Ref!$C$3:$D$14,2,) -> #N/A | AF13: =AD13*AE13 -> #N/A
B14: =B13+1 -> 45964 | C14: 0.32361111 | D14: 0.73263889 | G14: =IF(AND(C14="",D14=""),"",IF(AND(C14<=$D$5,D14>=$E$5),8, IF(AND(Q14<4,Q14>0,R14>=0),8-S14,IF(AND(Q14<4,C14>$D$5,U14>5),T14-(S14+1), IF(AND(Q14>3,D14<$E$5),T14-S14,IF(AND(Q14>3,D14>=$E$5),9-S14,IF(AND(C14>$D$5,U14<=4),T14-S14,IF(AND(C14>$D$5,U14>4),U14-(S14+1),IF(AND(C14<=$D$5,U14>=5),T14-1,IF(AND(C14<=$D$5,T14<=4),T14,IF(AND(C14<=$D$5,T14<5),4,IF(U14>5,U14-1,IF(U14<=4,U14,0))))))))))))) -> 8 | H14: =IF(F14-E14*24=0,"",IF(ROUND((F14-E14)*24,2)>=6,ROUND((F14-E14)*24,2)-1,ROUND((F14-E14)*24,2))) | I14: Worked on billers module frontend, connecting forms and validation logic. | K14: =Billing!C39 -> 0 | L14: =Billing!D39 -> 0 | M14: ='Attendance Report - Manager'!G29 -> 8 | N14: ='Attendance Report - Manager'!H29 -> 0 | P14: =SUMIF(DailyAccomplishmentReport!$B$12:$B$26,B14,DailyAccomplishmentReport!$AP$12:$AP$26) -> 0 | Q14: =IF(C14<>"", (C14-$D$5)*24,0) -> -0.73333333 | R14: =IF(D14<>"", (D14-$E$5)*24,0) -> 0.083333333 | S14: =(ROUNDUP(Q14/0.5,0)*0.5 ) -> -1 | T14: =ROUND((D14-$D$5)*24,2) -> 9.08 | U14: =(D14-C14)*24 -> 9.8166667 | Z14: =VLOOKUP(B14,Ref!$F$3:$H$367,3,FALSE) -> #N/A | AA14: =SUMIF(DailyAccomplishmentReport!$B$12:$B$43,B14,DailyAccomplishmentReport!$D$12:$D$43) -> 0 | AB14: =IF(F14=$F$9,2,IF(AND(E14>=0,F14<=$F$8),(F14-E14)*24,IF(F14>$E$9,(F14-$E$9)*24,0))) -> 0 | AC14: =ROUND(AB14*$AC$11,2) -> 0 | AD14: =ROUND((F14-E14)*24,2) -> 0 | AE14: =VLOOKUP(Z14,Ref!$C$3:$D$14,2,) -> #N/A | AF14: =AD14*AE14 -> #N/A
B15: =B14+1 -> 45965 | C15: 0.33819444 | D15: 0.73125 | G15: =IF(AND(C15="",D15=""),"",IF(AND(C15<=$D$5,D15>=$E$5),8, IF(AND(Q15<4,Q15>0,R15>=0),8-S15,IF(AND(Q15<4,C15>$D$5,U15>5),T15-(S15+1), IF(AND(Q15>3,D15<$E$5),T15-S15,IF(AND(Q15>3,D15>=$E$5),9-S15,IF(AND(C15>$D$5,U15<=4),T15-S15,IF(AND(C15>$D$5,U15>4),U15-(S15+1),IF(AND(C15<=$D$5,U15>=5),T15-1,IF(AND(C15<=$D$5,T15<=4),T15,IF(AND(C15<=$D$5,T15<5),4,IF(U15>5,U15-1,IF(U15<=4,U15,0))))))))))))) -> 8 | H15: =IF(F15-E15*24=0,"",IF(ROUND((F15-E15)*24,2)>=6,ROUND((F15-E15)*24,2)-1,ROUND((F15-E15)*24,2))) | I15: Worked on billers module frontend, connecting forms and validation logic. | K15: =Billing!C40 -> 0 | L15: =Billing!D40 -> 0 | M15: ='Attendance Report - Manager'!G30 -> 8 | N15: ='Attendance Report - Manager'!H30 -> 0 | P15: =SUMIF(DailyAccomplishmentReport!$B$12:$B$26,B15,DailyAccomplishmentReport!$AP$12:$AP$26) -> 0 | Q15: =IF(C15<>"", (C15-$D$5)*24,0) -> -0.38333333 | R15: =IF(D15<>"", (D15-$E$5)*24,0) -> 0.05 | S15: =(ROUNDUP(Q15/0.5,0)*0.5 ) -> -0.5 | T15: =ROUND((D15-$D$5)*24,2) -> 9.05 | U15: =(D15-C15)*24 -> 9.4333333 | Z15: =VLOOKUP(B15,Ref!$F$3:$H$367,3,FALSE) -> #N/A | AA15: =SUMIF(DailyAccomplishmentReport!$B$12:$B$43,B15,DailyAccomplishmentReport!$D$12:$D$43) -> 0 | AB15: =IF(F15=$F$9,2,IF(AND(E15>=0,F15<=$F$8),(F15-E15)*24,IF(F15>$E$9,(F15-$E$9)*24,0))) -> 0 | AC15: =ROUND(AB15*$AC$11,2) -> 0 | AD15: =ROUND((F15-E15)*24,2) -> 0 | AE15: =VLOOKUP(Z15,Ref!$C$3:$D$14,2,) -> #N/A | AF15: =AD15*AE15 -> #N/A
B16: =B15+1 -> 45966 | C16: 0.325 | D16: 0.72916667 | G16: =IF(AND(C16="",D16=""),"",IF(AND(C16<=$D$5,D16>=$E$5),8, IF(AND(Q16<4,Q16>0,R16>=0),8-S16,IF(AND(Q16<4,C16>$D$5,U16>5),T16-(S16+1), IF(AND(Q16>3,D16<$E$5),T16-S16,IF(AND(Q16>3,D16>=$E$5),9-S16,IF(AND(C16>$D$5,U16<=4),T16-S16,IF(AND(C16>$D$5,U16>4),U16-(S16+1),IF(AND(C16<=$D$5,U16>=5),T16-1,IF(AND(C16<=$D$5,T16<=4),T16,IF(AND(C16<=$D$5,T16<5),4,IF(U16>5,U16-1,IF(U16<=4,U16,0))))))))))))) -> 8 | H16: =IF(F16-E16*24=0,"",IF(ROUND((F16-E16)*24,2)>=6,ROUND((F16-E16)*24,2)-1,ROUND((F16-E16)*24,2))) | I16: Began coding the frontend components for the dashboard, setting up initial UI elements. | K16: =Billing!C41 -> 0 | L16: =Billing!D41 -> 0 | M16: ='Attendance Report - Manager'!G31 -> 8 | N16: ='Attendance Report - Manager'!H31 -> 0 | P16: =SUMIF(DailyAccomplishmentReport!$B$12:$B$26,B16,DailyAccomplishmentReport!$AP$12:$AP$26) -> 0 | Q16: =IF(C16<>"", (C16-$D$5)*24,0) -> -0.7 | R16: =IF(D16<>"", (D16-$E$5)*24,0) -> 0 | S16: =(ROUNDUP(Q16/0.5,0)*0.5 ) -> -1 | T16: =ROUND((D16-$D$5)*24,2) -> 9 | U16: =(D16-C16)*24 -> 9.7 | Z16: =VLOOKUP(B16,Ref!$F$3:$H$367,3,FALSE) -> #N/A | AA16: =SUMIF(DailyAccomplishmentReport!$B$12:$B$43,B16,DailyAccomplishmentReport!$D$12:$D$43) -> 0 | AB16: =IF(F16=$F$9,2,IF(AND(E16>=0,F16<=$F$8),(F16-E16)*24,IF(F16>$E$9,(F16-$E$9)*24,0))) -> 0 | AC16: =ROUND(AB16*$AC$11,2) -> 0 | AD16: =ROUND((F16-E16)*24,2) -> 0 | AE16: =VLOOKUP(Z16,Ref!$C$3:$D$14,2,) -> #N/A | AF16: =AD16*AE16 -> #N/A
B17: =B16+1 -> 45967 | C17: 0.33402778 | D17: 0.72916667 | G17: =IF(AND(C17="",D17=""),"",IF(AND(C17<=$D$5,D17>=$E$5),8, IF(AND(Q17<4,Q17>0,R17>=0),8-S17,IF(AND(Q17<4,C17>$D$5,U17>5),T17-(S17+1), IF(AND(Q17>3,D17<$E$5),T17-S17,IF(AND(Q17>3,D17>=$E$5),9-S17,IF(AND(C17>$D$5,U17<=4),T17-S17,IF(AND(C17>$D$5,U17>4),U17-(S17+1),IF(AND(C17<=$D$5,U17>=5),T17-1,IF(AND(C17<=$D$5,T17<=4),T17,IF(AND(C17<=$D$5,T17<5),4,IF(U17>5,U17-1,IF(U17<=4,U17,0))))))))))))) -> 8 | H17: =IF(F17-E17*24=0,"",IF(ROUND((F17-E17)*24,2)>=6,ROUND((F17-E17)*24,2)-1,ROUND((F17-E17)*24,2))) | I17: Worked on billers module frontend, connecting forms and validation logic. | K17: =Billing!C42 -> 0 | L17: =Billing!D42 -> 0 | M17: ='Attendance Report - Manager'!G32 -> 8 | N17: ='Attendance Report - Manager'!H32 -> 0 | P17: =SUMIF(DailyAccomplishmentReport!$B$12:$B$26,B17,DailyAccomplishmentReport!$AP$12:$AP$26) -> 0 | Q17: =IF(C17<>"", (C17-$D$5)*24,0) -> -0.48333333 | R17: =IF(D17<>"", (D17-$E$5)*24,0) -> 0 | S17: =(ROUNDUP(Q17/0.5,0)*0.5 ) -> -0.5 | T17: =ROUND((D17-$D$5)*24,2) -> 9 | U17: =(D17-C17)*24 -> 9.4833333 | Z17: =VLOOKUP(B17,Ref!$F$3:$H$367,3,FALSE) -> #N/A | AA17: =SUMIF(DailyAccomplishmentReport!$B$12:$B$43,B17,DailyAccomplishmentReport!$D$12:$D$43) -> 0 | AB17: =IF(F17=$F$9,2,IF(AND(E17>=0,F17<=$F$8),(F17-E17)*24,IF(F17>$E$9,(F17-$E$9)*24,0))) -> 0 | AC17: =ROUND(AB17*$AC$11,2) -> 0 | AD17: =ROUND((F17-E17)*24,2) -> 0 | AE17: =VLOOKUP(Z17,Ref!$C$3:$D$14,2,) -> #N/A | AF17: =AD17*AE17 -> #N/A
B18: =B17+1 -> 45968 | C18: 0.30069444 | D18: 0.73541667 | G18: =IF(AND(C18="",D18=""),"",IF(AND(C18<=$D$5,D18>=$E$5),8, IF(AND(Q18<4,Q18>0,R18>=0),8-S18,IF(AND(Q18<4,C18>$D$5,U18>5),T18-(S18+1), IF(AND(Q18>3,D18<$E$5),T18-S18,IF(AND(Q18>3,D18>=$E$5),9-S18,IF(AND(C18>$D$5,U18<=4),T18-S18,IF(AND(C18>$D$5,U18>4),U18-(S18+1),IF(AND(C18<=$D$5,U18>=5),T18-1,IF(AND(C18<=$D$5,T18<=4),T18,IF(AND(C18<=$D$5,T18<5),4,IF(U18>5,U18-1,IF(U18<=4,U18,0))))))))))))) -> 8 | H18: =IF(F18-E18*24=0,"",IF(ROUND((F18-E18)*24,2)>=6,ROUND((F18-E18)*24,2)-1,ROUND((F18-E18)*24,2))) | I18: Working on PDF CDeveloped frontend modules for the attendance feature, ensuring usability and accuracy.onverter reseach and implementation how to convert docx to pdf | K18: =Billing!C43 -> 0 | L18: =Billing!D43 -> 0 | M18: ='Attendance Report - Manager'!G33 -> 8 | N18: ='Attendance Report - Manager'!H33 -> 0 | P18: =SUMIF(DailyAccomplishmentReport!$B$12:$B$26,B18,DailyAccomplishmentReport!$AP$12:$AP$26) -> 0 | Q18: =IF(C18<>"", (C18-$D$5)*24,0) -> -1.2833333 | R18: =IF(D18<>"", (D18-$E$5)*24,0) -> 0.15 | S18: =(ROUNDUP(Q18/0.5,0)*0.5 ) -> -1.5 | T18: =ROUND((D18-$D$5)*24,2) -> 9.15 | U18: =(D18-C18)*24 -> 10.433333 | Z18: =VLOOKUP(B18,Ref!$F$3:$H$367,3,FALSE) -> #N/A | AA18: =SUMIF(DailyAccomplishmentReport!$B$12:$B$43,B18,DailyAccomplishmentReport!$D$12:$D$43) -> 0 | AB18: =IF(F18=$F$9,2,IF(AND(E18>=0,F18<=$F$8),(F18-E18)*24,IF(F18>$E$9,(F18-$E$9)*24,0))) -> 0 | AC18: =ROUND(AB18*$AC$11,2) -> 0 | AD18: =ROUND((F18-E18)*24,2) -> 0 | AE18: =VLOOKUP(Z18,Ref!$C$3:$D$14,2,) -> #N/A | AF18: =AD18*AE18 -> #N/A
B19: =B18+1 -> 45969 | G19: =IF(AND(C19="",D19=""),"",IF(AND(C19<=$D$5,D19>=$E$5),8, IF(AND(Q19<4,Q19>0,R19>=0),8-S19,IF(AND(Q19<4,C19>$D$5,U19>5),T19-(S19+1), IF(AND(Q19>3,D19<$E$5),T19-S19,IF(AND(Q19>3,D19>=$E$5),9-S19,IF(AND(C19>$D$5,U19<=4),T19-S19,IF(AND(C19>$D$5,U19>4),U19-(S19+1),IF(AND(C19<=$D$5,U19>=5),T19-1,IF(AND(C19<=$D$5,T19<=4),T19,IF(AND(C19<=$D$5,T19<5),4,IF(U19>5,U19-1,IF(U19<=4,U19,0))))))))))))) | K19: =Billing!C44 -> 0 | L19: =Billing!D44 -> 0 | M19: ='Attendance Report - Manager'!G34 -> 0 | N19: ='Attendance Report - Manager'!H34 -> 0 | P19: =SUMIF(DailyAccomplishmentReport!$B$12:$B$26,B19,DailyAccomplishmentReport!$AP$12:$AP$26) -> 0 | Q19: =IF(C19<>"", (C19-$D$5)*24,0) -> 0 | R19: =IF(D19<>"", (D19-$E$5)*24,0) -> 0 | S19: =(ROUNDUP(Q19/0.5,0)*0.5 ) -> 0 | T19: =ROUND((D19-$D$5)*24,2) -> -8.5 | U19: =(D19-C19)*24 -> 0 | Z19: =VLOOKUP(B19,Ref!$F$3:$H$367,3,FALSE) -> #N/A | AA19: =SUMIF(DailyAccomplishmentReport!$B$12:$B$43,B19,DailyAccomplishmentReport!$D$12:$D$43) -> 0 | AB19: =IF(F19=$F$9,2,IF(AND(E19>=0,F19<=$F$8),(F19-E19)*24,IF(F19>$E$9,(F19-$E$9)*24,0))) -> 0 | AC19: =ROUND(AB19*$AC$11,2) -> 0 | AD19: =ROUND((F19-E19)*24,2) -> 0 | AE19: =VLOOKUP(Z19,Ref!$C$3:$D$14,2,) -> #N/A | AF19: =AD19*AE19 -> #N/A
B20: =B19+1 -> 45970 | G20: =IF(AND(C20="",D20=""),"",IF(AND(C20<=$D$5,D20>=$E$5),8, IF(AND(Q20<4,Q20>0,R20>=0),8-S20,IF(AND(Q20<4,C20>$D$5,U20>5),T20-(S20+1), IF(AND(Q20>3,D20<$E$5),T20-S20,IF(AND(Q20>3,D20>=$E$5),9-S20,IF(AND(C20>$D$5,U20<=4),T20-S20,IF(AND(C20>$D$5,U20>4),U20-(S20+1),IF(AND(C20<=$D$5,U20>=5),T20-1,IF(AND(C20<=$D$5,T20<=4),T20,IF(AND(C20<=$D$5,T20<5),4,IF(U20>5,U20-1,IF(U20<=4,U20,0))))))))))))) | K20: =Billing!C45 -> 0 | L20: =Billing!D45 -> 0 | M20: ='Attendance Report - Manager'!G35 -> 0 | N20: ='Attendance Report - Manager'!H35 -> 0 | P20: =SUMIF(DailyAccomplishmentReport!$B$12:$B$26,B20,DailyAccomplishmentReport!$AP$12:$AP$26) -> 0 | Q20: =IF(C20<>"", (C20-$D$5)*24,0) -> 0 | R20: =IF(D20<>"", (D20-$E$5)*24,0) -> 0 | S20: =(ROUNDUP(Q20/0.5,0)*0.5 ) -> 0 | T20: =ROUND((D20-$D$5)*24,2) -> -8.5 | U20: =(D20-C20)*24 -> 0 | Z20: =VLOOKUP(B20,Ref!$F$3:$H$367,3,FALSE) -> #N/A | AA20: =SUMIF(DailyAccomplishmentReport!$B$12:$B$43,B20,DailyAccomplishmentReport!$D$12:$D$43) -> 0 | AB20: =IF(F20=$F$9,2,IF(AND(E20>=0,F20<=$F$8),(F20-E20)*24,IF(F20>$E$9,(F20-$E$9)*24,0))) -> 0 | AC20: =ROUND(AB20*$AC$11,2) -> 0 | AD20: =ROUND((F20-E20)*24,2) -> 0 | AE20: =VLOOKUP(Z20,Ref!$C$3:$D$14,2,) -> #N/A | AF20: =AD20*AE20 -> #N/A
B21: =B20+1 -> 45971 | G21: =IF(AND(C21="",D21=""),"",IF(AND(C21<=$D$5,D21>=$E$5),8, IF(AND(Q21<4,Q21>0,R21>=0),8-S21,IF(AND(Q21<4,C21>$D$5,U21>5),T21-(S21+1), IF(AND(Q21>3,D21<$E$5),T21-S21,IF(AND(Q21>3,D21>=$E$5),9-S21,IF(AND(C21>$D$5,U21<=4),T21-S21,IF(AND(C21>$D$5,U21>4),U21-(S21+1),IF(AND(C21<=$D$5,U21>=5),T21-1,IF(AND(C21<=$D$5,T21<=4),T21,IF(AND(C21<=$D$5,T21<5),4,IF(U21>5,U21-1,IF(U21<=4,U21,0))))))))))))) | K21: =Billing!C46 -> 0 | L21: =Billing!D46 -> 0 | M21: ='Attendance Report - Manager'!G36 -> 0 | N21: ='Attendance Report - Manager'!H36 -> 0 | P21: =SUMIF(DailyAccomplishmentReport!$B$12:$B$26,B21,DailyAccomplishmentReport!$AP$12:$AP$26) -> 0 | Q21: =IF(C21<>"", (C21-$D$5)*24,0) -> 0 | R21: =IF(D21<>"", (D21-$E$5)*24,0) -> 0 | S21: =(ROUNDUP(Q21/0.5,0)*0.5 ) -> 0 | T21: =ROUND((D21-$D$5)*24,2) -> -8.5 | U21: =(D21-C21)*24 -> 0 | Z21: =VLOOKUP(B21,Ref!$F$3:$H$367,3,FALSE) -> #N/A | AA21: =SUMIF(DailyAccomplishmentReport!$B$12:$B$43,B21,DailyAccomplishmentReport!$D$12:$D$43) -> 0 | AB21: =IF(F21=$F$9,2,IF(AND(E21>=0,F21<=$F$8),(F21-E21)*24,IF(F21>$E$9,(F21-$E$9)*24,0))) -> 0 | AC21: =ROUND(AB21*$AC$11,2) -> 0 | AD21: =ROUND((F21-E21)*24,2) -> 0 | AE21: =VLOOKUP(Z21,Ref!$C$3:$D$14,2,) -> #N/A | AF21: =AD21*AE21 -> #N/A
B22: =B21+1 -> 45972 | C22: 0.33263889 | D22: 0.72916667 | G22: =IF(AND(C22="",D22=""),"",IF(AND(C22<=$D$5,D22>=$E$5),8, IF(AND(Q22<4,Q22>0,R22>=0),8-S22,IF(AND(Q22<4,C22>$D$5,U22>5),T22-(S22+1), IF(AND(Q22>3,D22<$E$5),T22-S22,IF(AND(Q22>3,D22>=$E$5),9-S22,IF(AND(C22>$D$5,U22<=4),T22-S22,IF(AND(C22>$D$5,U22>4),U22-(S22+1),IF(AND(C22<=$D$5,U22>=5),T22-1,IF(AND(C22<=$D$5,T22<=4),T22,IF(AND(C22<=$D$5,T22<5),4,IF(U22>5,U22-1,IF(U22<=4,U22,0))))))))))))) -> 8 | H22: =IF(F22-E22*24=0,"",IF(ROUND((F22-E22)*24,2)>=6,ROUND((F22-E22)*24,2)-1,ROUND((F22-E22)*24,2))) | I22: Worked on billers module frontend, connecting forms and validation logic. | K22: =Billing!C47 -> 0 | L22: =Billing!D47 -> 0 | M22: ='Attendance Report - Manager'!G37 -> 8 | N22: ='Attendance Report - Manager'!H37 -> 0 | P22: =SUMIF(DailyAccomplishmentReport!$B$12:$B$26,B22,DailyAccomplishmentReport!$AP$12:$AP$26) -> 0 | Q22: =IF(C22<>"", (C22-$D$5)*24,0) -> -0.51666667 | R22: =IF(D22<>"", (D22-$E$5)*24,0) -> 0 | S22: =(ROUNDUP(Q22/0.5,0)*0.5 ) -> -1 | T22: =ROUND((D22-$D$5)*24,2) -> 9 | U22: =(D22-C22)*24 -> 9.5166667 | Z22: =VLOOKUP(B22,Ref!$F$3:$H$367,3,FALSE) -> #N/A | AA22: =SUMIF(DailyAccomplishmentReport!$B$12:$B$43,B22,DailyAccomplishmentReport!$D$12:$D$43) -> 0 | AB22: =IF(F22=$F$9,2,IF(AND(E22>=0,F22<=$F$8),(F22-E22)*24,IF(F22>$E$9,(F22-$E$9)*24,0))) -> 0 | AC22: =ROUND(AB22*$AC$11,2) -> 0 | AD22: =ROUND((F22-E22)*24,2) -> 0 | AE22: =VLOOKUP(Z22,Ref!$C$3:$D$14,2,) -> #N/A | AF22: =AD22*AE22 -> #N/A
B23: =B22+1 -> 45973 | C23: 0.325 | D23: 0.63888889 | G23: =IF(AND(C23="",D23=""),"",IF(AND(C23<=$D$5,D23>=$E$5),8, IF(AND(Q23<4,Q23>0,R23>=0),8-S23,IF(AND(Q23<4,C23>$D$5,U23>5),T23-(S23+1), IF(AND(Q23>3,D23<$E$5),T23-S23,IF(AND(Q23>3,D23>=$E$5),9-S23,IF(AND(C23>$D$5,U23<=4),T23-S23,IF(AND(C23>$D$5,U23>4),U23-(S23+1),IF(AND(C23<=$D$5,U23>=5),T23-1,IF(AND(C23<=$D$5,T23<=4),T23,IF(AND(C23<=$D$5,T23<5),4,IF(U23>5,U23-1,IF(U23<=4,U23,0))))))))))))) -> 5.83 | H23: =IF(F23-E23*24=0,"",IF(ROUND((F23-E23)*24,2)>=6,ROUND((F23-E23)*24,2)-1,ROUND((F23-E23)*24,2))) | I23: Adjusted and fixed backend issues | K23: =Billing!C48 -> 0 | L23: =Billing!D48 -> 0 | M23: ='Attendance Report - Manager'!G38 -> 6.53 | N23: ='Attendance Report - Manager'!H38 -> 0 | P23: =SUMIF(DailyAccomplishmentReport!$B$12:$B$26,B23,DailyAccomplishmentReport!$AP$12:$AP$26) -> 0 | Q23: =IF(C23<>"", (C23-$D$5)*24,0) -> -0.7 | R23: =IF(D23<>"", (D23-$E$5)*24,0) -> -2.1666667 | S23: =(ROUNDUP(Q23/0.5,0)*0.5 ) -> -1 | T23: =ROUND((D23-$D$5)*24,2) -> 6.83 | U23: =(D23-C23)*24 -> 7.5333333 | Z23: =VLOOKUP(B23,Ref!$F$3:$H$367,3,FALSE) -> #N/A | AA23: =SUMIF(DailyAccomplishmentReport!$B$12:$B$43,B23,DailyAccomplishmentReport!$D$12:$D$43) -> 0 | AB23: =IF(F23=$F$9,2,IF(AND(E23>=0,F23<=$F$8),(F23-E23)*24,IF(F23>$E$9,(F23-$E$9)*24,0))) -> 0 | AC23: =ROUND(AB23*$AC$11,2) -> 0 | AD23: =ROUND((F23-E23)*24,2) -> 0 | AE23: =VLOOKUP(Z23,Ref!$C$3:$D$14,2,) -> #N/A | AF23: =AD23*AE23 -> #N/A
B24: =B23+1 -> 45974 | C24: 0.33472222 | D24: 0.72916667 | G24: =IF(AND(C24="",D24=""),"",IF(AND(C24<=$D$5,D24>=$E$5),8, IF(AND(Q24<4,Q24>0,R24>=0),8-S24,IF(AND(Q24<4,C24>$D$5,U24>5),T24-(S24+1), IF(AND(Q24>3,D24<$E$5),T24-S24,IF(AND(Q24>3,D24>=$E$5),9-S24,IF(AND(C24>$D$5,U24<=4),T24-S24,IF(AND(C24>$D$5,U24>4),U24-(S24+1),IF(AND(C24<=$D$5,U24>=5),T24-1,IF(AND(C24<=$D$5,T24<=4),T24,IF(AND(C24<=$D$5,T24<5),4,IF(U24>5,U24-1,IF(U24<=4,U24,0))))))))))))) -> 8 | H24: =IF(F24-E24*24=0,"",IF(ROUND((F24-E24)*24,2)>=6,ROUND((F24-E24)*24,2)-1,ROUND((F24-E24)*24,2))) | I24: Finalized backend adjustments | K24: =Billing!C49 -> 0 | L24: =Billing!D49 -> 0 | M24: ='Attendance Report - Manager'!G39 -> 8 | N24: ='Attendance Report - Manager'!H39 -> 0 | P24: =SUMIF(DailyAccomplishmentReport!$B$12:$B$26,B24,DailyAccomplishmentReport!$AP$12:$AP$26) -> 0 | Q24: =IF(C24<>"", (C24-$D$5)*24,0) -> -0.46666667 | R24: =IF(D24<>"", (D24-$E$5)*24,0) -> 0 | S24: =(ROUNDUP(Q24/0.5,0)*0.5 ) -> -0.5 | T24: =ROUND((D24-$D$5)*24,2) -> 9 | U24: =(D24-C24)*24 -> 9.4666667 | Z24: =VLOOKUP(B24,Ref!$F$3:$H$367,3,FALSE) -> #N/A | AA24: =SUMIF(DailyAccomplishmentReport!$B$12:$B$43,B24,DailyAccomplishmentReport!$D$12:$D$43) -> 0 | AB24: =IF(F24=$F$9,2,IF(AND(E24>=0,F24<=$F$8),(F24-E24)*24,IF(F24>$E$9,(F24-$E$9)*24,0))) -> 0 | AC24: =ROUND(AB24*$AC$11,2) -> 0 | AD24: =ROUND((F24-E24)*24,2) -> 0 | AE24: =VLOOKUP(Z24,Ref!$C$3:$D$14,2,) -> #N/A | AF24: =AD24*AE24 -> #N/A
B25: =B24+1 -> 45975 | C25: 0.29305556 | D25: 0.72916667 | G25: =IF(AND(C25="",D25=""),"",IF(AND(C25<=$D$5,D25>=$E$5),8, IF(AND(Q25<4,Q25>0,R25>=0),8-S25,IF(AND(Q25<4,C25>$D$5,U25>5),T25-(S25+1), IF(AND(Q25>3,D25<$E$5),T25-S25,IF(AND(Q25>3,D25>=$E$5),9-S25,IF(AND(C25>$D$5,U25<=4),T25-S25,IF(AND(C25>$D$5,U25>4),U25-(S25+1),IF(AND(C25<=$D$5,U25>=5),T25-1,IF(AND(C25<=$D$5,T25<=4),T25,IF(AND(C25<=$D$5,T25<5),4,IF(U25>5,U25-1,IF(U25<=4,U25,0))))))))))))) -> 8 | H25: =IF(F25-E25*24=0,"",IF(ROUND((F25-E25)*24,2)>=6,ROUND((F25-E25)*24,2)-1,ROUND((F25-E25)*24,2))) | I25: Conducted thorough debugging across modules | K25: =Billing!C50 -> 0 | L25: =Billing!D50 -> 0 | M25: ='Attendance Report - Manager'!G40 -> 8 | N25: ='Attendance Report - Manager'!H40 -> 0 | P25: =SUMIF(DailyAccomplishmentReport!$B$12:$B$26,B25,DailyAccomplishmentReport!$AP$12:$AP$26) -> 0 | Q25: =IF(C25<>"", (C25-$D$5)*24,0) -> -1.4666667 | R25: =IF(D25<>"", (D25-$E$5)*24,0) -> 0 | S25: =(ROUNDUP(Q25/0.5,0)*0.5 ) -> -1.5 | T25: =ROUND((D25-$D$5)*24,2) -> 9 | U25: =(D25-C25)*24 -> 10.466667 | Z25: =VLOOKUP(B25,Ref!$F$3:$H$367,3,FALSE) -> #N/A | AA25: =SUMIF(DailyAccomplishmentReport!$B$12:$B$43,B25,DailyAccomplishmentReport!$D$12:$D$43) -> 0 | AB25: =IF(F25=$F$9,2,IF(AND(E25>=0,F25<=$F$8),(F25-E25)*24,IF(F25>$E$9,(F25-$E$9)*24,0))) -> 0 | AC25: =ROUND(AB25*$AC$11,2) -> 0 | AD25: =ROUND((F25-E25)*24,2) -> 0 | AE25: =VLOOKUP(Z25,Ref!$C$3:$D$14,2,) -> #N/A | AF25: =AD25*AE25 -> #N/A
B26: =B25+1 -> 45976 | G26: =IF(AND(C26="",D26=""),"",IF(AND(C26<=$D$5,D26>=$E$5),8, IF(AND(Q26<4,Q26>0,R26>=0),8-S26,IF(AND(Q26<4,C26>$D$5,U26>5),T26-(S26+1), IF(AND(Q26>3,D26<$E$5),T26-S26,IF(AND(Q26>3,D26>=$E$5),9-S26,IF(AND(C26>$D$5,U26<=4),T26-S26,IF(AND(C26>$D$5,U26>4),U26-(S26+1),IF(AND(C26<=$D$5,U26>=5),T26-1,IF(AND(C26<=$D$5,T26<=4),T26,IF(AND(C26<=$D$5,T26<5),4,IF(U26>5,U26-1,IF(U26<=4,U26,0))))))))))))) | H26: =IF(F26-E26*24=0,"",IF(ROUND((F26-E26)*24,2)>=6,ROUND((F26-E26)*24,2)-1,ROUND((F26-E26)*24,2))) | K26: =Billing!C51 -> 0 | L26: =Billing!D51 -> 0 | M26: ='Attendance Report - Manager'!G41 -> 0 | N26: ='Attendance Report - Manager'!H41 -> 0 | P26: =SUMIF(DailyAccomplishmentReport!$B$12:$B$26,B26,DailyAccomplishmentReport!$AP$12:$AP$26) -> 0 | Q26: =IF(C26<>"", (C26-$D$5)*24,0) -> 0 | R26: =IF(D26<>"", (D26-$E$5)*24,0) -> 0 | S26: =(ROUNDUP(Q26/0.5,0)*0.5 ) -> 0 | T26: =ROUND((D26-$D$5)*24,2) -> -8.5 | U26: =(D26-C26)*24 -> 0 | Z26: =VLOOKUP(B26,Ref!$F$3:$H$367,3,FALSE) -> #N/A | AA26: =SUMIF(DailyAccomplishmentReport!$B$12:$B$43,B26,DailyAccomplishmentReport!$D$12:$D$43) -> 0 | AB26: =IF(F26=$F$9,2,IF(AND(E26>=0,F26<=$F$8),(F26-E26)*24,IF(F26>$E$9,(F26-$E$9)*24,0))) -> 0 | AC26: =ROUND(AB26*$AC$11,2) -> 0 | AD26: =ROUND((F26-E26)*24,2) -> 0 | AE26: =VLOOKUP(Z26,Ref!$C$3:$D$14,2,) -> #N/A | AF26: =AD26*AE26 -> #N/A
G27: =IF(AND(C27="",D27=""),"",IF(AND(C27<=$D$5,D27>=$E$5),8, IF(AND(Q28<4,Q28>0,R28>=0),8-S28,IF(AND(Q28<4,C27>$D$5,U28>5),T28-(S28+1), IF(AND(Q28>3,D27<$E$5),T28-S28,IF(AND(Q28>3,D27>=$E$5),9-S28,IF(AND(C27>$D$5,U28<=4),T28-S28,IF(AND(C27>$D$5,U28>4),U28-(S28+1),IF(AND(C27<=$D$5,U28>=5),T28-1,IF(AND(C27<=$D$5,T28<=4),T28,IF(AND(C27<=$D$5,T28<5),4,IF(U28>5,U28-1,IF(U28<=4,U28,0))))))))))))) | K27: =Billing!C52 -> 0 | L27: =Billing!D52 -> 0 | M27: ='Attendance Report - Manager'!G42 -> #REF! | N27: ='Attendance Report - Manager'!H42 -> #REF! | P27: =SUMIF(DailyAccomplishmentReport!$B$12:$B$26,#REF!,DailyAccomplishmentReport!$AP$12:$AP$26) -> 0 | Q27: =IF(#REF!<>"", (#REF!-$D$5)*24,0) -> #REF! | R27: =IF(#REF!<>"", (#REF!-$E$5)*24,0) -> #REF! | S27: =(ROUNDUP(Q27/0.5,0)*0.5 ) -> #REF! | T27: =ROUND((#REF!-$D$5)*24,2) -> #REF! | U27: =(#REF!-#REF!)*24 -> #REF! | Z27: =VLOOKUP(#REF!,Ref!$F$3:$H$367,3,FALSE) -> #REF! | AA27: =SUMIF(DailyAccomplishmentReport!$B$12:$B$43,#REF!,DailyAccomplishmentReport!$D$12:$D$43) -> 0 | AB27: =IF(#REF!=$F$9,2,IF(AND(#REF!>=0,#REF!<=$F$8),(#REF!-#REF!)*24,IF(#REF!>$E$9,(#REF!-$E$9)*24,0))) -> #REF! | AC27: =ROUND(AB27*$AC$11,2) -> #REF! | AD27: =ROUND((#REF!-#REF!)*24,2) -> #REF! | AE27: =VLOOKUP(Z27,Ref!$C$3:$D$14,2,) -> #REF! | AF27: =AD27*AE27 -> #REF!
C28: Total | G28: =SUM(G12:G27) -> 69.83 | H28: =SUM(H12:H27) -> 0
B30: Certified Correct: | H30: Reviewed: Approved:
B32: MIKAELLA ANDREA DEVELOS | H32: ='Attendance Report_Second'!H32:I32 -> JUN M. SALVANERA | J32: ='Attendance Report_Second'!J32 -> HELEN D. PACIENCIA
B33: --------------------------------------------------------- | H33: ------------------------------------------- -----------------------------------------------
B34: Employee Signature over Printed Name | H34: Reviewed By Approved By
H35: (Signature over Printed Name) (Signature over Printed Name)

Sheet Attendance Report_Second
B1: RADIX
B4: Name | D4: MIKAELLA ANDREA DEVELOS
B5: Shift Schedule | D5: 0.35416667 | E5: 0.72916667 | F5: 0.00069444444 | G5: =E5-F5 -> 0.72847222
B6: Client | D6: Maybank Phil. Inc.
B7: Payroll Period | D7: From | E7: To
D8: 45977 | E8: 11/30/35 | F8: 0.25
E9: 0.91666667 | F9: 1
B10: Date | C10: Regular Hrs | E10: Overtime | G10: Total Hrs | I10: Remarks
C11: In | D11: Out | E11: In | F11: Out | G11: Regular | H11: OT | AB11: Night Diff | AC11: 0.1 | AD11: OTs | AE11: Int(%) | AF11: OT Total
B12: =D8 -> 45977 | H12: =IF(F12-E12*24=0,"",IF(ROUND((F12-E12)*24,2)>=6,ROUND((F12-E12)*24,2)-1,ROUND((F12-E12)*24,2))) | K12: =Billing!C22 -> 0 | L12: =Billing!D22 -> 0 | M12: ='Attendance Report - Manager'!G12 -> 0 | N12: ='Attendance Report - Manager'!H12 -> 0 | P12: =SUMIF(DailyAccomplishmentReport!$B$12:$B$26,B12,DailyAccomplishmentReport!$AP$12:$AP$26) -> 0 | Q12: =IF(C12<>"", (C12-$D$5)*24,0) -> 0 | R12: =IF(D12<>"", (D12-$E$5)*24,0) -> 0 | S12: =(ROUNDUP(Q12/0.5,0)*0.5 ) -> 0 | T12: =ROUND((D12-$D$5)*24,2) -> -8.5 | U12: =(D12-C12)*24 -> 0 | Z12: =VLOOKUP(B12,Ref!$F$3:$H$367,3,FALSE) -> #N/A | AA12: =SUMIF(DailyAccomplishmentReport!$B$12:$B$43,B12,DailyAccomplishmentReport!$D$12:$D$43) -> 0 | AB12: =IF(F12=$F$9,2,IF(AND(E12>=0,F12<=$F$8),(F12-E12)*24,IF(F12>$E$9,(F12-$E$9)*24,0))) -> 0 | AC12: =ROUND(AB12*$AC$11,2) -> 0 | AD12: =ROUND((F12-E12)*24,2) -> 0 | AE12: =VLOOKUP(Z12,Ref!$C$3:$D$14,2,) -> #N/A | AF12: =AD12*AE12 -> #N/A
B13: =B12+1 -> 45978 | C13: 0.35416667 | D13: 0.76805556 | G13: =IF(AND(C13="",D13=""),"",IF(AND(C13<=$D$5,D13>=$E$5),8, IF(AND(Q13<4,Q13>0,R13>=0),8-S13,IF(AND(Q13<4,C13>$D$5,U13>5),T13-(S13+1), IF(AND(Q13>3,D13<$E$5),T13-S13,IF(AND(Q13>3,D13>=$E$5),9-S13,IF(AND(C13>$D$5,U13<=4),T13-S13,IF(AND(C13>$D$5,U13>4),U13-(S13+1),IF(AND(C13<=$D$5,U13>=5),T13-1,IF(AND(C13<=$D$5,T13<=4),T13,IF(AND(C13<=$D$5,T13<5),4,IF(U13>5,U13-1,IF(U13<=4,U13,0))))))))))))) -> 8 | H13: =IF(F13-E13*24=0,"",IF(ROUND((F13-E13)*24,2)>=6,ROUND((F13-E13)*24,2)-1,ROUND((F13-E13)*24,2))) | I13: Worked on billers module frontend, connecting forms and validation logic. | K13: =Billing!C23 -> 0 | L13: =Billing!D23 -> 0 | M13: ='Attendance Report - Manager'!G13 -> 8 | N13: ='Attendance Report - Manager'!H13 -> 0 | P13: =SUMIF(DailyAccomplishmentReport!$B$12:$B$26,B13,DailyAccomplishmentReport!$AP$12:$AP$26) -> 0 | Q13: =IF(C13<>"", (C13-$D$5)*24,0) -> 0 | R13: =IF(D13<>"", (D13-$E$5)*24,0) -> 0.93333333 | S13: =(ROUNDUP(Q13/0.5,0)*0.5 ) -> 0 | T13: =ROUND((D13-$D$5)*24,2) -> 9.93 | U13: =(D13-C13)*24 -> 9.9333333 | Z13: =VLOOKUP(B13,Ref!$F$3:$H$367,3,FALSE) -> #N/A | AA13: =SUMIF(DailyAccomplishmentReport!$B$12:$B$43,B13,DailyAccomplishmentReport!$D$12:$D$43) -> 0 | AB13: =IF(F13=$F$9,2,IF(AND(E13>=0,F13<=$F$8),(F13-E13)*24,IF(F13>$E$9,(F13-$E$9)*24,0))) -> 0 | AC13: =ROUND(AB13*$AC$11,2) -> 0 | AD13: =ROUND((F13-E13)*24,2) -> 0 | AE13: =VLOOKUP(Z13,Ref!$C$3:$D$14,2,) -> #N/A | AF13: =AD13*AE13 -> #N/A
B14: =B13+1 -> 45979 | C14: 0.34236111 | D14: 0.77361111 | G14: =IF(AND(C14="",D14=""),"",IF(AND(C14<=$D$5,D14>=$E$5),8, IF(AND(Q14<4,Q14>0,R14>=0),8-S14,IF(AND(Q14<4,C14>$D$5,U14>5),T14-(S14+1), IF(AND(Q14>3,D14<$E$5),T14-S14,IF(AND(Q14>3,D14>=$E$5),9-S14,IF(AND(C14>$D$5,U14<=4),T14-S14,IF(AND(C14>$D$5,U14>4),U14-(S14+1),IF(AND(C14<=$D$5,U14>=5),T14-1,IF(AND(C14<=$D$5,T14<=4),T14,IF(AND(C14<=$D$5,T14<5),4,IF(U14>5,U14-1,IF(U14<=4,U14,0))))))))))))) -> 8 | H14: =IF(F14-E14*24=0,"",IF(ROUND((F14-E14)*24,2)>=6,ROUND((F14-E14)*24,2)-1,ROUND((F14-E14)*24,2))) | I14: Worked on billers module frontend, connecting forms and validation logic. | K14: =Billing!C24 -> 0 | L14: =Billing!D24 -> 0 | M14: ='Attendance Report - Manager'!G14 -> 8 | N14: ='Attendance Report - Manager'!H14 -> 0 | P14: =SUMIF(DailyAccomplishmentReport!$B$12:$B$26,B14,DailyAccomplishmentReport!$AP$12:$AP$26) -> 0 | Q14: =IF(C14<>"", (C14-$D$5)*24,0) -> -0.28333333 | R14: =IF(D14<>"", (D14-$E$5)*24,0) -> 1.0666667 | S14: =(ROUNDUP(Q14/0.5,0)*0.5 ) -> -0.5 | T14: =ROUND((D14-$D$5)*24,2) -> 10.07 | U14: =(D14-C14)*24 -> 10.35 | Z14: =VLOOKUP(B14,Ref!$F$3:$H$367,3,FALSE) -> #N/A | AA14: =SUMIF(DailyAccomplishmentReport!$B$12:$B$43,B14,DailyAccomplishmentReport!$D$12:$D$43) -> 0 | AB14: =IF(F14=$F$9,2,IF(AND(E14>=0,F14<=$F$8),(F14-E14)*24,IF(F14>$E$9,(F14-$E$9)*24,0))) -> 0 | AC14: =ROUND(AB14*$AC$11,2) -> 0 | AD14: =ROUND((F14-E14)*24,2) -> 0 | AE14: =VLOOKUP(Z14,Ref!$C$3:$D$14,2,) -> #N/A | AF14: =AD14*AE14 -> #N/A
B15: =B14+1 -> 45980 | C15: 0.32708333 | D15: 0.7625 | G15: =IF(AND(C15="",D15=""),"",IF(AND(C15<=$D$5,D15>=$E$5),8, IF(AND(Q15<4,Q15>0,R15>=0),8-S15,IF(AND(Q15<4,C15>$D$5,U15>5),T15-(S15+1), IF(AND(Q15>3,D15<$E$5),T15-S15,IF(AND(Q15>3,D15>=$E$5),9-S15,IF(AND(C15>$D$5,U15<=4),T15-S15,IF(AND(C15>$D$5,U15>4),U15-(S15+1),IF(AND(C15<=$D$5,U15>=5),T15-1,IF(AND(C15<=$D$5,T15<=4),T15,IF(AND(C15<=$D$5,T15<5),4,IF(U15>5,U15-1,IF(U15<=4,U15,0))))))))))))) -> 8 | H15: =IF(F15-E15*24=0,"",IF(ROUND((F15-E15)*24,2)>=6,ROUND((F15-E15)*24,2)-1,ROUND((F15-E15)*24,2))) | I15: Worked on billers module frontend, connecting forms and validation logic. | K15: =Billing!C25 -> 0 | L15: =Billing!D25 -> 0 | M15: ='Attendance Report - Manager'!G15 -> 8 | N15: ='Attendance Report - Manager'!H15 -> 0 | P15: =SUMIF(DailyAccomplishmentReport!$B$12:$B$26,B15,DailyAccomplishmentReport!$AP$12:$AP$26) -> 0 | Q15: =IF(C15<>"", (C15-$D$5)*24,0) -> -0.65 | R15: =IF(D15<>"", (D15-$E$5)*24,0) -> 0.8 | S15: =(ROUNDUP(Q15/0.5,0)*0.5 ) -> -1 | T15: =ROUND((D15-$D$5)*24,2) -> 9.8 | U15: =(D15-C15)*24 -> 10.45 | Z15: =VLOOKUP(B15,Ref!$F$3:$H$367,3,FALSE) -> #N/A | AA15: =SUMIF(DailyAccomplishmentReport!$B$12:$B$43,B15,DailyAccomplishmentReport!$D$12:$D$43) -> 0 | AB15: =IF(F15=$F$9,2,IF(AND(E15>=0,F15<=$F$8),(F15-E15)*24,IF(F15>$E$9,(F15-$E$9)*24,0))) -> 0 | AC15: =ROUND(AB15*$AC$11,2) -> 0 | AD15: =ROUND((F15-E15)*24,2) -> 0 | AE15: =VLOOKUP(Z15,Ref!$C$3:$D$14,2,) -> #N/A | AF15: =AD15*AE15 -> #N/A
B16: =B15+1 -> 45981 | C16: 0.35416667 | D16: 0.79375 | G16: =IF(AND(C16="",D16=""),"",IF(AND(C16<=$D$5,D16>=$E$5),8, IF(AND(Q16<4,Q16>0,R16>=0),8-S16,IF(AND(Q16<4,C16>$D$5,U16>5),T16-(S16+1), IF(AND(Q16>3,D16<$E$5),T16-S16,IF(AND(Q16>3,D16>=$E$5),9-S16,IF(AND(C16>$D$5,U16<=4),T16-S16,IF(AND(C16>$D$5,U16>4),U16-(S16+1),IF(AND(C16<=$D$5,U16>=5),T16-1,IF(AND(C16<=$D$5,T16<=4),T16,IF(AND(C16<=$D$5,T16<5),4,IF(U16>5,U16-1,IF(U16<=4,U16,0))))))))))))) -> 8 | H16: =IF(F16-E16*24=0,"",IF(ROUND((F16-E16)*24,2)>=6,ROUND((F16-E16)*24,2)-1,ROUND((F16-E16)*24,2))) | I16: Assisted instapay testing | K16: =Billing!C26 -> 0 | L16: =Billing!D26 -> 0 | M16: ='Attendance Report - Manager'!G16 -> 8 | N16: ='Attendance Report - Manager'!H16 -> 0 | P16: =SUMIF(DailyAccomplishmentReport!$B$12:$B$26,B16,DailyAccomplishmentReport!$AP$12:$AP$26) -> 0 | Q16: =IF(C16<>"", (C16-$D$5)*24,0) -> 0 | R16: =IF(D16<>"", (D16-$E$5)*24,0) -> 1.55 | S16: =(ROUNDUP(Q16/0.5,0)*0.5 ) -> 0 | T16: =ROUND((D16-$D$5)*24,2) -> 10.55 | U16: =(D16-C16)*24 -> 10.55 | Z16: =VLOOKUP(B16,Ref!$F$3:$H$367,3,FALSE) -> #N/A | AA16: =SUMIF(DailyAccomplishmentReport!$B$12:$B$43,B16,DailyAccomplishmentReport!$D$12:$D$43) -> 0 | AB16: =IF(F16=$F$9,2,IF(AND(E16>=0,F16<=$F$8),(F16-E16)*24,IF(F16>$E$9,(F16-$E$9)*24,0))) -> 0 | AC16: =ROUND(AB16*$AC$11,2) -> 0 | AD16: =ROUND((F16-E16)*24,2) -> 0 | AE16: =VLOOKUP(Z16,Ref!$C$3:$D$14,2,) -> #N/A | AF16: =AD16*AE16 -> #N/A
B17: =B16+1 -> 45982 | C17: 0.32083333 | D17: 0.74513889 | G17: =IF(AND(C17="",D17=""),"",IF(AND(C17<=$D$5,D17>=$E$5),8, IF(AND(Q17<4,Q17>0,R17>=0),8-S17,IF(AND(Q17<4,C17>$D$5,U17>5),T17-(S17+1), IF(AND(Q17>3,D17<$E$5),T17-S17,IF(AND(Q17>3,D17>=$E$5),9-S17,IF(AND(C17>$D$5,U17<=4),T17-S17,IF(AND(C17>$D$5,U17>4),U17-(S17+1),IF(AND(C17<=$D$5,U17>=5),T17-1,IF(AND(C17<=$D$5,T17<=4),T17,IF(AND(C17<=$D$5,T17<5),4,IF(U17>5,U17-1,IF(U17<=4,U17,0))))))))))))) -> 8 | H17: =IF(F17-E17*24=0,"",IF(ROUND((F17-E17)*24,2)>=6,ROUND((F17-E17)*24,2)-1,ROUND((F17-E17)*24,2))) | I17: Assisted instapay testing | K17: =Billing!C27 -> 0 | L17: =Billing!D27 -> 0 | M17: ='Attendance Report - Manager'!G17 -> 8 | N17: ='Attendance Report - Manager'!H17 -> 0 | P17: =SUMIF(DailyAccomplishmentReport!$B$12:$B$26,B17,DailyAccomplishmentReport!$AP$12:$AP$26) -> 0 | Q17: =IF(C17<>"", (C17-$D$5)*24,0) -> -0.8 | R17: =IF(D17<>"", (D17-$E$5)*24,0) -> 0.38333333 | S17: =(ROUNDUP(Q17/0.5,0)*0.5 ) -> -1 | T17: =ROUND((D17-$D$5)*24,2) -> 9.38 | U17: =(D17-C17)*24 -> 10.183333 | Z17: =VLOOKUP(B17,Ref!$F$3:$H$367,3,FALSE) -> #N/A | AA17: =SUMIF(DailyAccomplishmentReport!$B$12:$B$43,B17,DailyAccomplishmentReport!$D$12:$D$43) -> 0 | AB17: =IF(F17=$F$9,2,IF(AND(E17>=0,F17<=$F$8),(F17-E17)*24,IF(F17>$E$9,(F17-$E$9)*24,0))) -> 0 | AC17: =ROUND(AB17*$AC$11,2) -> 0 | AD17: =ROUND((F17-E17)*24,2) -> 0 | AE17: =VLOOKUP(Z17,Ref!$C$3:$D$14,2,) -> #N/A | AF17: =AD17*AE17 -> #N/A
B18: =B17+1 -> 45983 | G18: =IF(AND(C18="",D18=""),"",IF(AND(C18<=$D$5,D18>=$E$5),8, IF(AND(Q18<4,Q18>0,R18>=0),8-S18,IF(AND(Q18<4,C18>$D$5,U18>5),T18-(S18+1), IF(AND(Q18>3,D18<$E$5),T18-S18,IF(AND(Q18>3,D18>=$E$5),9-S18,IF(AND(C18>$D$5,U18<=4),T18-S18,IF(AND(C18>$D$5,U18>4),U18-(S18+1),IF(AND(C18<=$D$5,U18>=5),T18-1,IF(AND(C18<=$D$5,T18<=4),T18,IF(AND(C18<=$D$5,T18<5),4,IF(U18>5,U18-1,IF(U18<=4,U18,0))))))))))))) | H18: =IF(F18-E18*24=0,"",IF(ROUND((F18-E18)*24,2)>=6,ROUND((F18-E18)*24,2)-1,ROUND((F18-E18)*24,2))) | K18: =Billing!C28 -> 0 | L18: =Billing!D28 -> 0 | M18: ='Attendance Report - Manager'!G18 -> 0 | N18: ='Attendance Report - Manager'!H18 -> 0 | P18: =SUMIF(DailyAccomplishmentReport!$B$12:$B$26,B18,DailyAccomplishmentReport!$AP$12:$AP$26) -> 0 | Q18: =IF(C18<>"", (C18-$D$5)*24,0) -> 0 | R18: =IF(D18<>"", (D18-$E$5)*24,0) -> 0 | S18: =(ROUNDUP(Q18/0.5,0)*0.5 ) -> 0 | T18: =ROUND((D18-$D$5)*24,2) -> -8.5 | U18: =(D18-C18)*24 -> 0 | Z18: =VLOOKUP(B18,Ref!$F$3:$H$367,3,FALSE) -> #N/A | AA18: =SUMIF(DailyAccomplishmentReport!$B$12:$B$43,B18,DailyAccomplishmentReport!$D$12:$D$43) -> 0 | AB18: =IF(F18=$F$9,2,IF(AND(E18>=0,F18<=$F$8),(F18-E18)*24,IF(F18>$E$9,(F18-$E$9)*24,0))) -> 0 | AC18: =ROUND(AB18*$AC$11,2) -> 0 | AD18: =ROUND((F18-E18)*24,2) -> 0 | AE18: =VLOOKUP(Z18,Ref!$C$3:$D$14,2,) -> #N/A | AF18: =AD18*AE18 -> #N/A
B19: =B18+1 -> 45984 | H19: =IF(F19-E19*24=0,"",IF(ROUND((F19-E19)*24,2)>=6,ROUND((F19-E19)*24,2)-1,ROUND((F19-E19)*24,2))) | K19: =Billing!C29 -> 0 | L19: =Billing!D29 -> 0 | M19: ='Attendance Report - Manager'!G19 -> 0 | N19: ='Attendance Report - Manager'!H19 -> 0 | P19: =SUMIF(DailyAccomplishmentReport!$B$12:$B$26,B19,DailyAccomplishmentReport!$AP$12:$AP$26) -> 0 | Q19: =IF(C19<>"", (C19-$D$5)*24,0) -> 0 | R19: =IF(D19<>"", (D19-$E$5)*24,0) -> 0 | S19: =(ROUNDUP(Q19/0.5,0)*0.5 ) -> 0 | T19: =ROUND((D19-$D$5)*24,2) -> -8.5 | U19: =(D19-C19)*24 -> 0 | Z19: =VLOOKUP(B19,Ref!$F$3:$H$367,3,FALSE) -> #N/A | AA19: =SUMIF(DailyAccomplishmentReport!$B$12:$B$43,B19,DailyAccomplishmentReport!$D$12:$D$43) -> 0 | AB19: =IF(F19=$F$9,2,IF(AND(E19>=0,F19<=$F$8),(F19-E19)*24,IF(F19>$E$9,(F19-$E$9)*24,0))) -> 0 | AC19: =ROUND(AB19*$AC$11,2) -> 0 | AD19: =ROUND((F19-E19)*24,2) -> 0 | AE19: =VLOOKUP(Z19,Ref!$C$3:$D$14,2,) -> #N/A | AF19: =AD19*AE19 -> #N/A
B20: =B19+1 -> 45985 | C20: 0.34583333 | D20: 0.73194444 | G20: =IF(AND(C20="",D20=""),"",IF(AND(C20<=$D$5,D20>=$E$5),8, IF(AND(Q20<4,Q20>0,R20>=0),8-S20,IF(AND(Q20<4,C20>$D$5,U20>5),T20-(S20+1), IF(AND(Q20>3,D20<$E$5),T20-S20,IF(AND(Q20>3,D20>=$E$5),9-S20,IF(AND(C20>$D$5,U20<=4),T20-S20,IF(AND(C20>$D$5,U20>4),U20-(S20+1),IF(AND(C20<=$D$5,U20>=5),T20-1,IF(AND(C20<=$D$5,T20<=4),T20,IF(AND(C20<=$D$5,T20<5),4,IF(U20>5,U20-1,IF(U20<=4,U20,0))))))))))))) -> 8 | H20: =IF(F20-E20*24=0,"",IF(ROUND((F20-E20)*24,2)>=6,ROUND((F20-E20)*24,2)-1,ROUND((F20-E20)*24,2))) | I20: Worked on instapay dashboard | K20: =Billing!C30 -> 0 | L20: =Billing!D30 -> 0 | M20: ='Attendance Report - Manager'!G20 -> 8 | N20: ='Attendance Report - Manager'!H20 -> 0 | P20: =SUMIF(DailyAccomplishmentReport!$B$12:$B$26,B20,DailyAccomplishmentReport!$AP$12:$AP$26) -> 0 | Q20: =IF(C20<>"", (C20-$D$5)*24,0) -> -0.2 | R20: =IF(D20<>"", (D20-$E$5)*24,0) -> 0.066666667 | S20: =(ROUNDUP(Q20/0.5,0)*0.5 ) -> -0.5 | T20: =ROUND((D20-$D$5)*24,2) -> 9.07 | U20: =(D20-C20)*24 -> 9.2666667 | Z20: =VLOOKUP(B20,Ref!$F$3:$H$367,3,FALSE) -> #N/A | AA20: =SUMIF(DailyAccomplishmentReport!$B$12:$B$43,B20,DailyAccomplishmentReport!$D$12:$D$43) -> 0 | AB20: =IF(F20=$F$9,2,IF(AND(E20>=0,F20<=$F$8),(F20-E20)*24,IF(F20>$E$9,(F20-$E$9)*24,0))) -> 0 | AC20: =ROUND(AB20*$AC$11,2) -> 0 | AD20: =ROUND((F20-E20)*24,2) -> 0 | AE20: =VLOOKUP(Z20,Ref!$C$3:$D$14,2,) -> #N/A | AF20: =AD20*AE20 -> #N/A
B21: =B20+1 -> 45986 | C21: 8.3 | D21: 0.81875 | G21: 8 | H21: =IF(F21-E21*24=0,"",IF(ROUND((F21-E21)*24,2)>=6,ROUND((F21-E21)*24,2)-1,ROUND((F21-E21)*24,2))) | I21: assisted euronet and instapay testing | K21: =Billing!C31 -> 0 | L21: =Billing!D31 -> 0 | M21: ='Attendance Report - Manager'!G21 -> 0 | N21: ='Attendance Report - Manager'!H21 -> 0 | P21: =SUMIF(DailyAccomplishmentReport!$B$12:$B$26,B21,DailyAccomplishmentReport!$AP$12:$AP$26) -> 0 | Q21: =IF(C21<>"", (C21-$D$5)*24,0) -> 190.7 | R21: =IF(D21<>"", (D21-$E$5)*24,0) -> 2.15 | S21: =(ROUNDUP(Q21/0.5,0)*0.5 ) -> 191 | T21: =ROUND((D21-$D$5)*24,2) -> 11.15 | U21: =(D21-C21)*24 -> -179.55 | Z21: =VLOOKUP(B21,Ref!$F$3:$H$367,3,FALSE) -> #N/A | AA21: =SUMIF(DailyAccomplishmentReport!$B$12:$B$43,B21,DailyAccomplishmentReport!$D$12:$D$43) -> 0 | AB21: =IF(F21=$F$9,2,IF(AND(E21>=0,F21<=$F$8),(F21-E21)*24,IF(F21>$E$9,(F21-$E$9)*24,0))) -> 0 | AC21: =ROUND(AB21*$AC$11,2) -> 0 | AD21: =ROUND((F21-E21)*24,2) -> 0 | AE21: =VLOOKUP(Z21,Ref!$C$3:$D$14,2,) -> #N/A | AF21: =AD21*AE21 -> #N/A
B22: =B21+1 -> 45987 | C22: 0.35416667 | D22: 0.76111111 | G22: =IF(AND(C22="",D22=""),"",IF(AND(C22<=$D$5,D22>=$E$5),8, IF(AND(Q22<4,Q22>0,R22>=0),8-S22,IF(AND(Q22<4,C22>$D$5,U22>5),T22-(S22+1), IF(AND(Q22>3,D22<$E$5),T22-S22,IF(AND(Q22>3,D22>=$E$5),9-S22,IF(AND(C22>$D$5,U22<=4),T22-S22,IF(AND(C22>$D$5,U22>4),U22-(S22+1),IF(AND(C22<=$D$5,U22>=5),T22-1,IF(AND(C22<=$D$5,T22<=4),T22,IF(AND(C22<=$D$5,T22<5),4,IF(U22>5,U22-1,IF(U22<=4,U22,0))))))))))))) -> 8 | H22: =IF(F22-E22*24=0,"",IF(ROUND((F22-E22)*24,2)>=6,ROUND((F22-E22)*24,2)-1,ROUND((F22-E22)*24,2))) | I22: assisted euronet and instapay testing | K22: =Billing!C32 -> 0 | L22: =Billing!D32 -> 0 | M22: ='Attendance Report - Manager'!G22 -> 8 | N22: ='Attendance Report - Manager'!H22 -> 0 | P22: =SUMIF(DailyAccomplishmentReport!$B$12:$B$26,B22,DailyAccomplishmentReport!$AP$12:$AP$26) -> 0 | Q22: =IF(C22<>"", (C22-$D$5)*24,0) -> 0 | R22: =IF(D22<>"", (D22-$E$5)*24,0) -> 0.76666667 | S22: =(ROUNDUP(Q22/0.5,0)*0.5 ) -> 0 | T22: =ROUND((D22-$D$5)*24,2) -> 9.77 | U22: =(D22-C22)*24 -> 9.7666667 | Z22: =VLOOKUP(B22,Ref!$F$3:$H$367,3,FALSE) -> #N/A | AA22: =SUMIF(DailyAccomplishmentReport!$B$12:$B$43,B22,DailyAccomplishmentReport!$D$12:$D$43) -> 0 | AB22: =IF(F22=$F$9,2,IF(AND(E22>=0,F22<=$F$8),(F22-E22)*24,IF(F22>$E$9,(F22-$E$9)*24,0))) -> 0 | AC22: =ROUND(AB22*$AC$11,2) -> 0 | AD22: =ROUND((F22-E22)*24,2) -> 0 | AE22: =VLOOKUP(Z22,Ref!$C$3:$D$14,2,) -> #N/A | AF22: =AD22*AE22 -> #N/A
B23: 11/27/25 | C23: 9.35 | D23: 0.73888889 | G23: 8 | H23: =IF(F23-E23*24=0,"",IF(ROUND((F23-E23)*24,2)>=6,ROUND((F23-E23)*24,2)-1,ROUND((F23-E23)*24,2))) | I23: assisted euronet and instapay testing | K23: =Billing!C33 -> 0 | L23: =Billing!D33 -> 0 | M23: ='Attendance Report - Manager'!G23 -> 0 | N23: ='Attendance Report - Manager'!H23 -> 0 | P23: =SUMIF(DailyAccomplishmentReport!$B$12:$B$26,B23,DailyAccomplishmentReport!$AP$12:$AP$26) -> 0 | Q23: =IF(C23<>"", (C23-$D$5)*24,0) -> 215.9 | R23: =IF(D23<>"", (D23-$E$5)*24,0) -> 0.23333333 | S23: =(ROUNDUP(Q23/0.5,0)*0.5 ) -> 216 | T23: =ROUND((D23-$D$5)*24,2) -> 9.23 | U23: =(D23-C23)*24 -> -206.66667 | Z23: =VLOOKUP(B23,Ref!$F$3:$H$367,3,FALSE) -> #N/A | AA23: =SUMIF(DailyAccomplishmentReport!$B$12:$B$43,B23,DailyAccomplishmentReport!$D$12:$D$43) -> 0 | AB23: =IF(F23=$F$9,2,IF(AND(E23>=0,F23<=$F$8),(F23-E23)*24,IF(F23>$E$9,(F23-$E$9)*24,0))) -> 0 | AC23: =ROUND(AB23*$AC$11,2) -> 0 | AD23: =ROUND((F23-E23)*24,2) -> 0 | AE23: =VLOOKUP(Z23,Ref!$C$3:$D$14,2,) -> #N/A | AF23: =AD23*AE23 -> #N/A
B24: 11/28/25 | C24: 0.39583333 | D24: 0.82847222 | G24: 7 | I24: Worked on instapay dashboard's error | K24: =Billing!C34 -> 0 | L24: =Billing!D34 -> 0 | M24: ='Attendance Report - Manager'!G24 -> 8 | N24: ='Attendance Report - Manager'!H24 -> 0 | P24: =SUMIF(DailyAccomplishmentReport!$B$12:$B$26,B24,DailyAccomplishmentReport!$AP$12:$AP$26) -> 0 | Q24: =IF(C24<>"", (C24-$D$5)*24,0) -> 1 | R24: =IF(D24<>"", (D24-$E$5)*24,0) -> 2.3833333 | S24: =(ROUNDUP(Q24/0.5,0)*0.5 ) -> 1 | T24: =ROUND((D24-$D$5)*24,2) -> 11.38 | U24: =(D24-C24)*24 -> 10.383333 | Z24: =VLOOKUP(B24,Ref!$F$3:$H$367,3,FALSE) -> #N/A | AA24: =SUMIF(DailyAccomplishmentReport!$B$12:$B$43,B24,DailyAccomplishmentReport!$D$12:$D$43) -> 0 | AB24: =IF(F24=$F$9,2,IF(AND(E24>=0,F24<=$F$8),(F24-E24)*24,IF(F24>$E$9,(F24-$E$9)*24,0))) -> 0 | AC24: =ROUND(AB24*$AC$11,2) -> 0 | AD24: =ROUND((F24-E24)*24,2) -> 0 | AE24: =VLOOKUP(Z24,Ref!$C$3:$D$14,2,) -> #N/A | AF24: =AD24*AE24 -> #N/A
B25: 11/29/25 | H25: =IF(F25-E25*24=0,"",IF(ROUND((F25-E25)*24,2)>=6,ROUND((F25-E25)*24,2)-1,ROUND((F25-E25)*24,2))) | K25: =Billing!C35 -> 0 | L25: =Billing!D35 -> 0 | M25: ='Attendance Report - Manager'!G25 -> 0 | N25: ='Attendance Report - Manager'!H25 -> 0 | P25: =SUMIF(DailyAccomplishmentReport!$B$12:$B$26,B25,DailyAccomplishmentReport!$AP$12:$AP$26) -> 0 | Q25: =IF(C25<>"", (C25-$D$5)*24,0) -> 0 | R25: =IF(D25<>"", (D25-$E$5)*24,0) -> 0 | S25: =(ROUNDUP(Q25/0.5,0)*0.5 ) -> 0 | T25: =ROUND((D25-$D$5)*24,2) -> -8.5 | U25: =(D25-C25)*24 -> 0 | Z25: =VLOOKUP(B25,Ref!$F$3:$H$367,3,FALSE) -> #N/A | AA25: =SUMIF(DailyAccomplishmentReport!$B$12:$B$43,B25,DailyAccomplishmentReport!$D$12:$D$43) -> 0 | AB25: =IF(F25=$F$9,2,IF(AND(E25>=0,F25<=$F$8),(F25-E25)*24,IF(F25>$E$9,(F25-$E$9)*24,0))) -> 0 | AC25: =ROUND(AB25*$AC$11,2) -> 0 | AD25: =ROUND((F25-E25)*24,2) -> 0 | AE25: =VLOOKUP(Z25,Ref!$C$3:$D$14,2,) -> #N/A | AF25: =AD25*AE25 -> #N/A
B26: 11/30/25 | H26: =IF(F26-E26*24=0,"",IF(ROUND((F26-E26)*24,2)>=6,ROUND((F26-E26)*24,2)-1,ROUND((F26-E26)*24,2))) | K26: =Billing!C36 -> 0 | L26: =Billing!D36 -> 0 | M26: ='Attendance Report - Manager'!G26 -> 0 | N26: ='Attendance Report - Manager'!H26 -> 0 | P26: =SUMIF(DailyAccomplishmentReport!$B$12:$B$26,B26,DailyAccomplishmentReport!$AP$12:$AP$26) -> 0 | Q26: =IF(C26<>"", (C26-$D$5)*24,0) -> 0 | R26: =IF(D26<>"", (D26-$E$5)*24,0) -> 0 | S26: =(ROUNDUP(Q26/0.5,0)*0.5 ) -> 0 | T26: =ROUND((D26-$D$5)*24,2) -> -8.5 | U26: =(D26-C26)*24 -> 0 | Z26: =VLOOKUP(B26,Ref!$F$3:$H$367,3,FALSE) -> #N/A | AA26: =SUMIF(DailyAccomplishmentReport!$B$12:$B$43,B26,DailyAccomplishmentReport!$D$12:$D$43) -> 0 | AB26: =IF(F26=$F$9,2,IF(AND(E26>=0,F26<=$F$8),(F26-E26)*24,IF(F26>$E$9,(F26-$E$9)*24,0))) -> 0 | AC26: =ROUND(AB26*$AC$11,2) -> 0 | AD26: =ROUND((F26-E26)*24,2) -> 0 | AE26: =VLOOKUP(Z26,Ref!$C$3:$D$14,2,) -> #N/A | AF26: =AD26*AE26 -> #N/A
G27: =IF(AND(C27="",D27=""),"",IF(AND(C27<=$D$5,D27>=$E$5),8, IF(AND(Q27<4,Q27>0,R27>=0),8-S27,IF(AND(Q27<4,C27>$D$5,U27>5),T27-(S27+1), IF(AND(Q27>3,D27<$E$5),T27-S27,IF(AND(Q27>3,D27>=$E$5),9-S27,IF(AND(C27>$D$5,U27<=4),T27-S27,IF(AND(C27>$D$5,U27>4),U27-(S27+1),IF(AND(C27<=$D$5,U27>=5),T27-1,IF(AND(C27<=$D$5,T27<=4),T27,IF(AND(C27<=$D$5,T27<5),4,IF(U27>5,U27-1,IF(U27<=4,U27,0))))))))))))) | H27: =IF((AC27+AF27)=0,"",ROUND(AC27+AF27,2))
C28: Total | G28: =SUM(G12:G27) -> 79 | H28: =SUM(H12:H27) -> 0
B30: Certified Correct: | H30: Reviewed: Approved:
B32: =IF(DailyAccomplishmentReport!D3<>"",DailyAccomplishmentReport!D3,"") -> MIKAELLA ANDREA DEVELOS | H32: JUN M. SALVANERA | J32: HELEN D. PACIENCIA
B33: --------------------------------------------------------- | H33: ------------------------------------------- -----------------------------------------------
B34: Employee Signature over Printed Name | H34: Reviewed By Approved By
H35: (Signature over Printed Name) (Signature over Printed Name)

Sheet Attendance Report - Manager
B1: <Provider Logo>
B4: Name : | D4: =DailyAccomplishmentReport!D3:E3 -> MIKAELLA ANDREA DEVELOS
B5: Shift Schedule : | D5: ='Attendance Report_Second'!D5 -> 0.35416667 | E5: ='Attendance Report_Second'!E5 -> 0.72916667
B6: Client : | D6: Maybank Phil. Inc.
B7: Payroll Period : | D7: From | E7: To
D8: =DailyAccomplishmentReport!D8 -> 11/16/25 | E8: =DailyAccomplishmentReport!E8 -> 11/30/25
B10: Date | C10: Regular Hrs | E10: Overtime | G10: Total Hrs | I10: Remarks
C11: In | D11: Out | E11: In | F11: Out | G11: Regular | H11: OT
B12: =D8 -> 11/16/25 | C12: ='Attendance Report_Second'!C12 -> 0 | D12: ='Attendance Report_Second'!D12 -> 0 | E12: ='Attendance Report_Second'!E12 -> 0 | F12: ='Attendance Report_Second'!F12 -> 0 | G12: =IF(((D12-C12)*24-1)<0,0,IF(((D12-C12)*24)>9,8,ROUND(((D12-C12)*24-1),2))) -> 0 | H12: =IF(((F12-E12) *24 )>0,ROUND(((F12-E12) *24 ),2),0) -> 0 | K12: =Billing!C22 -> 0 | L12: =Billing!D22 -> 0
B13: =B12+1 -> #VALUE! | C13: ='Attendance Report_Second'!C13 -> 0.35416667 | D13: ='Attendance Report_Second'!D13 -> 0.76805556 | E13: ='Attendance Report_Second'!E13 -> 0 | F13: ='Attendance Report_Second'!F13 -> 0 | G13: =IF(((D13-C13)*24-1)<0,0,IF(((D13-C13)*24)>9,8,ROUND(((D13-C13)*24-1),2))) -> 8 | H13: =IF(((F13-E13) *24 )>0,ROUND(((F13-E13) *24 ),2),0) -> 0 | K13: =Billing!C23 -> 0 | L13: =Billing!D23 -> 0
B14: =B13+1 -> #VALUE! | C14: ='Attendance Report_Second'!C14 -> 0.34236111 | D14: ='Attendance Report_Second'!D14 -> 0.77361111 | E14: ='Attendance Report_Second'!E14 -> 0 | F14: ='Attendance Report_Second'!F14 -> 0 | G14: =IF(((D14-C14)*24-1)<0,0,IF(((D14-C14)*24)>9,8,ROUND(((D14-C14)*24-1),2))) -> 8 | H14: =IF(((F14-E14) *24 )>0,ROUND(((F14-E14) *24 ),2),0) -> 0 | K14: =Billing!C24 -> 0 | L14: =Billing!D24 -> 0
B15: =B14+1 -> #VALUE! | C15: ='Attendance Report_Second'!C15 -> 0.32708333 | D15: ='Attendance Report_Second'!D15 -> 0.7625 | E15: ='Attendance Report_Second'!E15 -> 0 | F15: ='Attendance Report_Second'!F15 -> 0 | G15: =IF(((D15-C15)*24-1)<0,0,IF(((D15-C15)*24)>9,8,ROUND(((D15-C15)*24-1),2))) -> 8 | H15: =IF(((F15-E15) *24 )>0,ROUND(((F15-E15) *24 ),2),0) -> 0 | K15: =Billing!C25 -> 0 | L15: =Billing!D25 -> 0
B16: =B15+1 -> #VALUE! | C16: ='Attendance Report_Second'!C16 -> 0.35416667 | D16: ='Attendance Report_Second'!D16 -> 0.79375 | E16: ='Attendance Report_Second'!E16 -> 0 | F16: ='Attendance Report_Second'!F16 -> 0 | G16: =IF(((D16-C16)*24-1)<0,0,IF(((D16-C16)*24)>9,8,ROUND(((D16-C16)*24-1),2))) -> 8 | H16: =IF(((F16-E16) *24 )>0,ROUND(((F16-E16) *24 ),2),0) -> 0 | K16: =Billing!C26 -> 0 | L16: =Billing!D26 -> 0
